Workbook

Sheet M電入力
A1: 通過駅画像番号 | B1: 25 | C1: 停車駅画像番号 | D1: 26 | E1: 終着駅画像番号 | F1: 27
A2: 00時画像番号 | B2: 24 | C2: 00分画像番号 | D2: 60 | E2: 00秒画像番号 | F2: 60
A3: ナンバー | B3: 駅名 | C3: 駅キロ | D3: 駅番号 | E3: 着(hh:mm:ss) | F3: 発(通)(hh:mm:ss) | G3: 駅番線 | H3: 制限速度IN | I3: 制限速度OUT | J3: 列車駅間時間 (マニュアル入力，hh:mm:ss) | K3: 停車？ | L3: 着hh | M3: 着mm | N3: 着ss | O3: 着hh00→24 | P3: 着mm00→60 | Q3: 着ss00→60 | R3: 着hh真 | S3: 発hh | T3: 発mm | U3: 発ss | V3: 発hh00→24 | W3: 発mm00→60 | X3: 発ss00→60 | Y3: 発hh真 | Z3: IsOverHour? | AA3: 列車着(hhmmss) | AB3: 列車発(通)(hhmmss) | AC3: 列車次駅設定 | AD3: 列車次駅着時刻 | AE3: 列車駅間時間 (自動計算)
A4: 1 | B4: 上 野 | C4: 3790 | D4: 50 | E4: 0.33055556 | F4: 0.33194444 | I4: 30 | J4: =F5-F4 -> 0.0024305556 | K4: =IF(E3="着(hh:mm:ss)","start",IF(E4="p","pass",IF(OR(F4="t",K3="terminal"),"terminal","stop"))) -> start | L4: {=TEXT(_xlfn.SWITCH(TRUE,E4="P",$B$1,AND(E4="",K4<>"TERMINAL"),$D$1,TRUE,HOUR(E4)),"00")} -> 07 | M4: {=TEXT(_xlfn.SWITCH(TRUE,E4="P","00",AND(E4="",K4<>"TERMINAL"),"00",TRUE,MINUTE(E4)),"00")} -> 56 | N4: {=TEXT(_xlfn.SWITCH(TRUE,E4="P","00",AND(E4="",K4<>"TERMINAL"),"00",TRUE,SECOND(E4)),"00")} -> 00 | O4: {=_xlfn.SWITCH(TRUE,AND(L4="00",K4<>"TERMINAL"),TEXT($B$2,"00"),L4=TEXT($B$1,"00"),TEXT($B$1,"00"),L4=TEXT($D$1,"00"),TEXT($D$1,"00"),TRUE,+L4)} -> 07 | P4: {=_xlfn.SWITCH(TRUE,OR(L4=TEXT($B$1,"00"),L4=TEXT($D$1,"00")),"00",AND(M4="00",K4<>"TERMINAL"),TEXT($D$2,"00"),TRUE,M4)} -> 56 | Q4: {=_xlfn.SWITCH(TRUE,OR(L4=TEXT($B$1,"00"),L4=TEXT($D$1,"00")),"00",AND(N4="00",K4<>"TERMINAL"),TEXT($F$2,"00"),TRUE,N4)} -> 60 | R4: =IF(OR(L4="25",L4="26"),TEXT(MAX(VALUE(R3),VALUE(Y3)),"00"),L4) -> 07 | S4: {=_xlfn.SWITCH(TRUE,F4="T",TEXT($F$1,"00"),AND(F4="",K4<>"TERMINAL"),"00",TRUE,TEXT(HOUR(F4),"00"))} -> 07 | T4: {=TEXT(_xlfn.SWITCH(TRUE,F4="T","00",AND(F4="",K4<>"TERMINAL"),"00",TRUE,MINUTE(F4)),"00")} -> 58 | U4: {=TEXT(_xlfn.SWITCH(TRUE,F4="T","00",AND(F4="",K4<>"TERMINAL"),"00",TRUE,SECOND(F4)),"00")} -> 00 | V4: {=_xlfn.SWITCH(TRUE,AND(S4="00",R4<>"TERMINAL"),TEXT($B$2,"00"),S4=TEXT($B$1,"00"),TEXT($B$1,"00"),S4=TEXT($D$1,"00"),TEXT($D$1,"00"),TRUE,+S4)} -> 07 | W4: {=_xlfn.SWITCH(TRUE,OR(S4=TEXT($B$1,"00"),S4=TEXT($D$1,"00")),"00",AND(T4="00",K4<>"TERMINAL"),TEXT($D$2,"00"),TRUE,T4)} -> 58 | X4: {=_xlfn.SWITCH(TRUE,OR(S4=TEXT($B$1,"00"),S4=TEXT($D$1,"00")),"00",AND(U4="00",K4<>"TERMINAL"),TEXT($F$2,"00"),TRUE,U4)} -> 60 | Y4: =IF(OR(S4="27"),S3,S4) -> 07 | Z4: =TEXT(TRUE,) -> TRUE | AA4: =IF(Z4="TRUE",O4&P4&Q4,IF(OR(L4="25",L4="26"),O4&P4&Q4,"00"&P4&Q4)) -> 075660 | AB4: =IF(Z4="TRUE",V4&W4&X4,IF(S4="27",V4&W4&X4,"00"&W4&X4)) -> 075860 | AC4: {=TEXT($D4,"000")&TEXT(IFERROR(INDEX($D$5:$D$103,_xlfn.AGGREGATE(15,6,ROW($E$5:$E$103)/(($E$5:$E$103<>"p")*($E$5:$E$103<>"t")*(ROW($E$5:$E$103)>ROW($E4))),1)-ROW($E$5)+1),$D4),"000")} -> 050053 | AD4: {=TEXT(_xlfn.XLOOKUP(TRUE, AA5:AA$103<>"250000", AA5:AA$103, "未找到"),"000000")} -> 000760 | AE4: {=_xlfn.SWITCH(TRUE,J4<>"",TEXT(J4,"MMSS"),TRUE,IFERROR(TEXT(E5-F4,"MMSS"),"0000"))} -> 0330
A5: 2 | B5: 井 堀 | C5: 6875 | D5: 51 | E5: p | F5: 0.334375 | I5: 60 | J5: =F6-F5 -> 0.00086805556 | K5: =IF(E4="着(hh:mm:ss)","start",IF(E5="p","pass",IF(OR(F5="t",K4="terminal"),"terminal","stop"))) -> pass | L5: {=TEXT(_xlfn.SWITCH(TRUE,E5="P",$B$1,AND(E5="",K5<>"TERMINAL"),$D$1,TRUE,HOUR(E5)),"00")} -> 25 | M5: {=TEXT(_xlfn.SWITCH(TRUE,E5="P","00",AND(E5="",K5<>"TERMINAL"),"00",TRUE,MINUTE(E5)),"00")} -> 00 | N5: {=TEXT(_xlfn.SWITCH(TRUE,E5="P","00",AND(E5="",K5<>"TERMINAL"),"00",TRUE,SECOND(E5)),"00")} -> 00 | O5: {=_xlfn.SWITCH(TRUE,AND(L5="00",K5<>"TERMINAL"),TEXT($B$2,"00"),L5=TEXT($B$1,"00"),TEXT($B$1,"00"),L5=TEXT($D$1,"00"),TEXT($D$1,"00"),TRUE,+L5)} -> 25 | P5: {=_xlfn.SWITCH(TRUE,OR(L5=TEXT($B$1,"00"),L5=TEXT($D$1,"00")),"00",AND(M5="00",K5<>"TERMINAL"),TEXT($D$2,"00"),TRUE,M5)} -> 00 | Q5: {=_xlfn.SWITCH(TRUE,OR(L5=TEXT($B$1,"00"),L5=TEXT($D$1,"00")),"00",AND(N5="00",K5<>"TERMINAL"),TEXT($F$2,"00"),TRUE,N5)} -> 00 | R5: =IF(OR(L5="25",L5="26"),TEXT(MAX(VALUE(R4),VALUE(Y4)),"00"),L5) -> 07 | S5: {=_xlfn.SWITCH(TRUE,F5="T",TEXT($F$1,"00"),AND(F5="",K5<>"TERMINAL"),"00",TRUE,TEXT(HOUR(F5),"00"))} -> 08 | T5: {=TEXT(_xlfn.SWITCH(TRUE,F5="T","00",AND(F5="",K5<>"TERMINAL"),"00",TRUE,MINUTE(F5)),"00")} -> 01 | U5: {=TEXT(_xlfn.SWITCH(TRUE,F5="T","00",AND(F5="",K5<>"TERMINAL"),"00",TRUE,SECOND(F5)),"00")} -> 30 | V5: =IF(AND(S5="00",F4<>"t",V4<>"00"),"24",S5) -> 08 | W5: {=_xlfn.SWITCH(TRUE,OR(S5=TEXT($B$1,"00"),S5=TEXT($D$1,"00")),"00",AND(T5="00",K5<>"TERMINAL"),TEXT($D$2,"00"),TRUE,T5)} -> 01 | X5: {=_xlfn.SWITCH(TRUE,OR(S5=TEXT($B$1,"00"),S5=TEXT($D$1,"00")),"00",AND(U5="00",K5<>"TERMINAL"),TEXT($F$2,"00"),TRUE,U5)} -> 30 | Y5: =IF(OR(S5="27"),S4,S5) -> 08 | Z5: =IF(OR(Y5>R5,R5>Y4),"TRUE","FALSE") -> TRUE | AA5: =IF(Z5="TRUE",O5&P5&Q5,IF(OR(L5="25",L5="26"),O5&P5&Q5,"00"&P5&Q5)) -> 250000 | AB5: =IF(Z5="TRUE",V5&W5&X5,IF(S5="27",V5&W5&X5,"00"&W5&X5)) -> 080130 | AC5: {=TEXT($D5,"000")&TEXT(IFERROR(INDEX($D$5:$D$103,_xlfn.AGGREGATE(15,6,ROW($E$5:$E$103)/(($E$5:$E$103<>"p")*($E$5:$E$103<>"t")*(ROW($E$5:$E$103)>ROW($E5))),1)-ROW($E$5)+1),$D5),"000")} -> 051053 | AD5: {=TEXT(_xlfn.XLOOKUP(TRUE, AA6:AA$103<>"250000", AA6:AA$103, "未找到"),"000000")} -> 000760 | AE5: {=_xlfn.SWITCH(TRUE,J5<>"",TEXT(J5,"MMSS"),TRUE,IFERROR(TEXT(E6-F5,"MMSS"),"0000"))} -> 0115
A6: 3 | B6: 尾 久 | C6: 8460 | D6: 52 | E6: p | F6: 0.33524306 | K6: =IF(E5="着(hh:mm:ss)","start",IF(E6="p","pass",IF(OR(F6="t",K5="terminal"),"terminal","stop"))) -> pass | L6: {=TEXT(_xlfn.SWITCH(TRUE,E6="P",$B$1,AND(E6="",K6<>"TERMINAL"),$D$1,TRUE,HOUR(E6)),"00")} -> 25 | M6: {=TEXT(_xlfn.SWITCH(TRUE,E6="P","00",AND(E6="",K6<>"TERMINAL"),"00",TRUE,MINUTE(E6)),"00")} -> 00 | N6: {=TEXT(_xlfn.SWITCH(TRUE,E6="P","00",AND(E6="",K6<>"TERMINAL"),"00",TRUE,SECOND(E6)),"00")} -> 00 | O6: {=_xlfn.SWITCH(TRUE,AND(L6="00",K6<>"TERMINAL"),TEXT($B$2,"00"),L6=TEXT($B$1,"00"),TEXT($B$1,"00"),L6=TEXT($D$1,"00"),TEXT($D$1,"00"),TRUE,+L6)} -> 25 | P6: {=_xlfn.SWITCH(TRUE,OR(L6=TEXT($B$1,"00"),L6=TEXT($D$1,"00")),"00",AND(M6="00",K6<>"TERMINAL"),TEXT($D$2,"00"),TRUE,M6)} -> 00 | Q6: {=_xlfn.SWITCH(TRUE,OR(L6=TEXT($B$1,"00"),L6=TEXT($D$1,"00")),"00",AND(N6="00",K6<>"TERMINAL"),TEXT($F$2,"00"),TRUE,N6)} -> 00 | R6: =IF(OR(L6="25",L6="26"),TEXT(MAX(VALUE(R5),VALUE(Y5)),"00"),L6) -> 08 | S6: {=_xlfn.SWITCH(TRUE,F6="T",TEXT($F$1,"00"),AND(F6="",K6<>"TERMINAL"),"00",TRUE,TEXT(HOUR(F6),"00"))} -> 08 | T6: {=TEXT(_xlfn.SWITCH(TRUE,F6="T","00",AND(F6="",K6<>"TERMINAL"),"00",TRUE,MINUTE(F6)),"00")} -> 02 | U6: {=TEXT(_xlfn.SWITCH(TRUE,F6="T","00",AND(F6="",K6<>"TERMINAL"),"00",TRUE,SECOND(F6)),"00")} -> 45 | V6: =IF(AND(S6="00",F5<>"t",V5<>"00"),"24",S6) -> 08 | W6: {=_xlfn.SWITCH(TRUE,OR(S6=TEXT($B$1,"00"),S6=TEXT($D$1,"00")),"00",AND(T6="00",K6<>"TERMINAL"),TEXT($D$2,"00"),TRUE,T6)} -> 02 | X6: {=_xlfn.SWITCH(TRUE,OR(S6=TEXT($B$1,"00"),S6=TEXT($D$1,"00")),"00",AND(U6="00",K6<>"TERMINAL"),TEXT($F$2,"00"),TRUE,U6)} -> 45 | Y6: =IF(OR(S6="27"),S5,S6) -> 08 | Z6: =IF(OR(Y6>R6,R6>Y5),"TRUE","FALSE") -> FALSE | AA6: =IF(Z6="TRUE",O6&P6&Q6,IF(OR(L6="25",L6="26"),O6&P6&Q6,"00"&P6&Q6)) -> 250000 | AB6: =IF(Z6="TRUE",V6&W6&X6,IF(S6="27",V6&W6&X6,"00"&W6&X6)) -> 000245 | AC6: {=TEXT($D6,"000")&TEXT(IFERROR(INDEX($D$5:$D$103,_xlfn.AGGREGATE(15,6,ROW($E$5:$E$103)/(($E$5:$E$103<>"p")*($E$5:$E$103<>"t")*(ROW($E$5:$E$103)>ROW($E6))),1)-ROW($E$5)+1),$D6),"000")} -> 052053 | AD6: {=TEXT(_xlfn.XLOOKUP(TRUE, AA7:AA$103<>"250000", AA7:AA$103, "未找到"),"000000")} -> 000760 | AE6: {=_xlfn.SWITCH(TRUE,J6<>"",TEXT(J6,"MMSS"),TRUE,IFERROR(TEXT(E7-F6,"MMSS"),"0000"))} -> 0415
A7: 4 | B7: 赤 羽 | C7: 13240 | D7: 53 | E7: 0.33819444 | F7: 0.33871528 | J7: =F8-F7 -> 0.0013888889 | K7: =IF(E6="着(hh:mm:ss)","start",IF(E7="p","pass",IF(OR(F7="t",K6="terminal"),"terminal","stop"))) -> stop | L7: {=TEXT(_xlfn.SWITCH(TRUE,E7="P",$B$1,AND(E7="",K7<>"TERMINAL"),$D$1,TRUE,HOUR(E7)),"00")} -> 08 | M7: {=TEXT(_xlfn.SWITCH(TRUE,E7="P","00",AND(E7="",K7<>"TERMINAL"),"00",TRUE,MINUTE(E7)),"00")} -> 07 | N7: {=TEXT(_xlfn.SWITCH(TRUE,E7="P","00",AND(E7="",K7<>"TERMINAL"),"00",TRUE,SECOND(E7)),"00")} -> 00 | O7: {=_xlfn.SWITCH(TRUE,AND(L7="00",K7<>"TERMINAL"),TEXT($B$2,"00"),L7=TEXT($B$1,"00"),TEXT($B$1,"00"),L7=TEXT($D$1,"00"),TEXT($D$1,"00"),TRUE,+L7)} -> 08 | P7: {=_xlfn.SWITCH(TRUE,OR(L7=TEXT($B$1,"00"),L7=TEXT($D$1,"00")),"00",AND(M7="00",K7<>"TERMINAL"),TEXT($D$2,"00"),TRUE,M7)} -> 07 | Q7: {=_xlfn.SWITCH(TRUE,OR(L7=TEXT($B$1,"00"),L7=TEXT($D$1,"00")),"00",AND(N7="00",K7<>"TERMINAL"),TEXT($F$2,"00"),TRUE,N7)} -> 60 | R7: =IF(OR(L7="25",L7="26"),TEXT(MAX(VALUE(R6),VALUE(Y6)),"00"),L7) -> 08 | S7: {=_xlfn.SWITCH(TRUE,F7="T",TEXT($F$1,"00"),AND(F7="",K7<>"TERMINAL"),"00",TRUE,TEXT(HOUR(F7),"00"))} -> 08 | T7: {=TEXT(_xlfn.SWITCH(TRUE,F7="T","00",AND(F7="",K7<>"TERMINAL"),"00",TRUE,MINUTE(F7)),"00")} -> 07 | U7: {=TEXT(_xlfn.SWITCH(TRUE,F7="T","00",AND(F7="",K7<>"TERMINAL"),"00",TRUE,SECOND(F7)),"00")} -> 45 | V7: =IF(AND(S7="00",F6<>"t",V6<>"00"),"24",S7) -> 08 | W7: {=_xlfn.SWITCH(TRUE,OR(S7=TEXT($B$1,"00"),S7=TEXT($D$1,"00")),"00",AND(T7="00",K7<>"TERMINAL"),TEXT($D$2,"00"),TRUE,T7)} -> 07 | X7: {=_xlfn.SWITCH(TRUE,OR(S7=TEXT($B$1,"00"),S7=TEXT($D$1,"00")),"00",AND(U7="00",K7<>"TERMINAL"),TEXT($F$2,"00"),TRUE,U7)} -> 45 | Y7: =IF(OR(S7="27"),S6,S7) -> 08 | Z7: =IF(OR(Y7>R7,R7>Y6),"TRUE","FALSE") -> FALSE | AA7: =IF(Z7="TRUE",O7&P7&Q7,IF(OR(L7="25",L7="26"),O7&P7&Q7,"00"&P7&Q7)) -> 000760 | AB7: =IF(Z7="TRUE",V7&W7&X7,IF(S7="27",V7&W7&X7,"00"&W7&X7)) -> 000745 | AC7: {=TEXT($D7,"000")&TEXT(IFERROR(INDEX($D$5:$D$103,_xlfn.AGGREGATE(15,6,ROW($E$5:$E$103)/(($E$5:$E$103<>"p")*($E$5:$E$103<>"t")*(ROW($E$5:$E$103)>ROW($E7))),1)-ROW($E$5)+1),$D7),"000")} -> 053066 | AD7: {=TEXT(_xlfn.XLOOKUP(TRUE, AA8:AA$103<>"250000", AA8:AA$103, "未找到"),"000000")} -> 001660 | AE7: {=_xlfn.SWITCH(TRUE,J7<>"",TEXT(J7,"MMSS"),TRUE,IFERROR(TEXT(E8-F7,"MMSS"),"0000"))} -> 0200
A8: 5 | B8: 川 口 | C8: 15880 | D8: 65 | E8: p | F8: 0.34010417 | K8: =IF(E7="着(hh:mm:ss)","start",IF(E8="p","pass",IF(OR(F8="t",K7="terminal"),"terminal","stop"))) -> pass | L8: {=TEXT(_xlfn.SWITCH(TRUE,E8="P",$B$1,AND(E8="",K8<>"TERMINAL"),$D$1,TRUE,HOUR(E8)),"00")} -> 25 | M8: {=TEXT(_xlfn.SWITCH(TRUE,E8="P","00",AND(E8="",K8<>"TERMINAL"),"00",TRUE,MINUTE(E8)),"00")} -> 00 | N8: {=TEXT(_xlfn.SWITCH(TRUE,E8="P","00",AND(E8="",K8<>"TERMINAL"),"00",TRUE,SECOND(E8)),"00")} -> 00 | O8: {=_xlfn.SWITCH(TRUE,AND(L8="00",K8<>"TERMINAL"),TEXT($B$2,"00"),L8=TEXT($B$1,"00"),TEXT($B$1,"00"),L8=TEXT($D$1,"00"),TEXT($D$1,"00"),TRUE,+L8)} -> 25 | P8: {=_xlfn.SWITCH(TRUE,OR(L8=TEXT($B$1,"00"),L8=TEXT($D$1,"00")),"00",AND(M8="00",K8<>"TERMINAL"),TEXT($D$2,"00"),TRUE,M8)} -> 00 | Q8: {=_xlfn.SWITCH(TRUE,OR(L8=TEXT($B$1,"00"),L8=TEXT($D$1,"00")),"00",AND(N8="00",K8<>"TERMINAL"),TEXT($F$2,"00"),TRUE,N8)} -> 00 | R8: =IF(OR(L8="25",L8="26"),TEXT(MAX(VALUE(R7),VALUE(Y7)),"00"),L8) -> 08 | S8: {=_xlfn.SWITCH(TRUE,F8="T",TEXT($F$1,"00"),AND(F8="",K8<>"TERMINAL"),"00",TRUE,TEXT(HOUR(F8),"00"))} -> 08 | T8: {=TEXT(_xlfn.SWITCH(TRUE,F8="T","00",AND(F8="",K8<>"TERMINAL"),"00",TRUE,MINUTE(F8)),"00")} -> 09 | U8: {=TEXT(_xlfn.SWITCH(TRUE,F8="T","00",AND(F8="",K8<>"TERMINAL"),"00",TRUE,SECOND(F8)),"00")} -> 45 | V8: =IF(AND(S8="00",F7<>"t",V7<>"00"),"24",S8) -> 08 | W8: {=_xlfn.SWITCH(TRUE,OR(S8=TEXT($B$1,"00"),S8=TEXT($D$1,"00")),"00",AND(T8="00",K8<>"TERMINAL"),TEXT($D$2,"00"),TRUE,T8)} -> 09 | X8: {=_xlfn.SWITCH(TRUE,OR(S8=TEXT($B$1,"00"),S8=TEXT($D$1,"00")),"00",AND(U8="00",K8<>"TERMINAL"),TEXT($F$2,"00"),TRUE,U8)} -> 45 | Y8: =IF(OR(S8="27"),S7,S8) -> 08 | Z8: =IF(OR(Y8>R8,R8>Y7),"TRUE","FALSE") -> FALSE | AA8: =IF(Z8="TRUE",O8&P8&Q8,IF(OR(L8="25",L8="26"),O8&P8&Q8,"00"&P8&Q8)) -> 250000 | AB8: =IF(Z8="TRUE",V8&W8&X8,IF(S8="27",V8&W8&X8,"00"&W8&X8)) -> 000945 | AC8: {=TEXT($D8,"000")&TEXT(IFERROR(INDEX($D$5:$D$103,_xlfn.AGGREGATE(15,6,ROW($E$5:$E$103)/(($E$5:$E$103<>"p")*($E$5:$E$103<>"t")*(ROW($E$5:$E$103)>ROW($E8))),1)-ROW($E$5)+1),$D8),"000")} -> 065066 | AD8: {=TEXT(_xlfn.XLOOKUP(TRUE, AA9:AA$103<>"250000", AA9:AA$103, "未找到"),"000000")} -> 001660 | AE8: {=_xlfn.SWITCH(TRUE,J8<>"",TEXT(J8,"MMSS"),TRUE,IFERROR(TEXT(E9-F8,"MMSS"),"0000"))} -> 0615
A9: 6 | B9: 浦 和 | C9: 24240 | D9: 66 | E9: 0.34444444 | F9: 0.34479167 | J9: =F10-F9 -> 0.0022569444 | K9: =IF(E8="着(hh:mm:ss)","start",IF(E9="p","pass",IF(OR(F9="t",K8="terminal"),"terminal","stop"))) -> stop | L9: {=TEXT(_xlfn.SWITCH(TRUE,E9="P",$B$1,AND(E9="",K9<>"TERMINAL"),$D$1,TRUE,HOUR(E9)),"00")} -> 08 | M9: {=TEXT(_xlfn.SWITCH(TRUE,E9="P","00",AND(E9="",K9<>"TERMINAL"),"00",TRUE,MINUTE(E9)),"00")} -> 16 | N9: {=TEXT(_xlfn.SWITCH(TRUE,E9="P","00",AND(E9="",K9<>"TERMINAL"),"00",TRUE,SECOND(E9)),"00")} -> 00 | O9: {=_xlfn.SWITCH(TRUE,AND(L9="00",K9<>"TERMINAL"),TEXT($B$2,"00"),L9=TEXT($B$1,"00"),TEXT($B$1,"00"),L9=TEXT($D$1,"00"),TEXT($D$1,"00"),TRUE,+L9)} -> 08 | P9: {=_xlfn.SWITCH(TRUE,OR(L9=TEXT($B$1,"00"),L9=TEXT($D$1,"00")),"00",AND(M9="00",K9<>"TERMINAL"),TEXT($D$2,"00"),TRUE,M9)} -> 16 | Q9: {=_xlfn.SWITCH(TRUE,OR(L9=TEXT($B$1,"00"),L9=TEXT($D$1,"00")),"00",AND(N9="00",K9<>"TERMINAL"),TEXT($F$2,"00"),TRUE,N9)} -> 60 | R9: =IF(OR(L9="25",L9="26"),TEXT(MAX(VALUE(R8),VALUE(Y8)),"00"),L9) -> 08 | S9: {=_xlfn.SWITCH(TRUE,F9="T",TEXT($F$1,"00"),AND(F9="",K9<>"TERMINAL"),"00",TRUE,TEXT(HOUR(F9),"00"))} -> 08 | T9: {=TEXT(_xlfn.SWITCH(TRUE,F9="T","00",AND(F9="",K9<>"TERMINAL"),"00",TRUE,MINUTE(F9)),"00")} -> 16 | U9: {=TEXT(_xlfn.SWITCH(TRUE,F9="T","00",AND(F9="",K9<>"TERMINAL"),"00",TRUE,SECOND(F9)),"00")} -> 30 | V9: =IF(AND(S9="00",F8<>"t",V8<>"00"),"24",S9) -> 08 | W9: {=_xlfn.SWITCH(TRUE,OR(S9=TEXT($B$1,"00"),S9=TEXT($D$1,"00")),"00",AND(T9="00",K9<>"TERMINAL"),TEXT($D$2,"00"),TRUE,T9)} -> 16 | X9: {=_xlfn.SWITCH(TRUE,OR(S9=TEXT($B$1,"00"),S9=TEXT($D$1,"00")),"00",AND(U9="00",K9<>"TERMINAL"),TEXT($F$2,"00"),TRUE,U9)} -> 30 | Y9: =IF(OR(S9="27"),S8,S9) -> 08 | Z9: =IF(OR(Y9>R9,R9>Y8),"TRUE","FALSE") -> FALSE | AA9: =IF(Z9="TRUE",O9&P9&Q9,IF(OR(L9="25",L9="26"),O9&P9&Q9,"00"&P9&Q9)) -> 001660 | AB9: =IF(Z9="TRUE",V9&W9&X9,IF(S9="27",V9&W9&X9,"00"&W9&X9)) -> 001630 | AC9: {=TEXT($D9,"000")&TEXT(IFERROR(INDEX($D$5:$D$103,_xlfn.AGGREGATE(15,6,ROW($E$5:$E$103)/(($E$5:$E$103<>"p")*($E$5:$E$103<>"t")*(ROW($E$5:$E$103)>ROW($E9))),1)-ROW($E$5)+1),$D9),"000")} -> 066069 | AD9: {=TEXT(_xlfn.XLOOKUP(TRUE, AA10:AA$103<>"250000", AA10:AA$103, "未找到"),"000000")} -> 002260 | AE9: {=_xlfn.SWITCH(TRUE,J9<>"",TEXT(J9,"MMSS"),TRUE,IFERROR(TEXT(E10-F9,"MMSS"),"0000"))} -> 0315
A10: 7 | B10: さ新都心 | C10: 28915 | D10: 67 | E10: p | F10: 0.34704861 | K10: =IF(E9="着(hh:mm:ss)","start",IF(E10="p","pass",IF(OR(F10="t",K9="terminal"),"terminal","stop"))) -> pass | L10: {=TEXT(_xlfn.SWITCH(TRUE,E10="P",$B$1,AND(E10="",K10<>"TERMINAL"),$D$1,TRUE,HOUR(E10)),"00")} -> 25 | M10: {=TEXT(_xlfn.SWITCH(TRUE,E10="P","00",AND(E10="",K10<>"TERMINAL"),"00",TRUE,MINUTE(E10)),"00")} -> 00 | N10: {=TEXT(_xlfn.SWITCH(TRUE,E10="P","00",AND(E10="",K10<>"TERMINAL"),"00",TRUE,SECOND(E10)),"00")} -> 00 | O10: {=_xlfn.SWITCH(TRUE,AND(L10="00",K10<>"TERMINAL"),TEXT($B$2,"00"),L10=TEXT($B$1,"00"),TEXT($B$1,"00"),L10=TEXT($D$1,"00"),TEXT($D$1,"00"),TRUE,+L10)} -> 25 | P10: {=_xlfn.SWITCH(TRUE,OR(L10=TEXT($B$1,"00"),L10=TEXT($D$1,"00")),"00",AND(M10="00",K10<>"TERMINAL"),TEXT($D$2,"00"),TRUE,M10)} -> 00 | Q10: {=_xlfn.SWITCH(TRUE,OR(L10=TEXT($B$1,"00"),L10=TEXT($D$1,"00")),"00",AND(N10="00",K10<>"TERMINAL"),TEXT($F$2,"00"),TRUE,N10)} -> 00 | R10: =IF(OR(L10="25",L10="26"),TEXT(MAX(VALUE(R9),VALUE(Y9)),"00"),L10) -> 08 | S10: {=_xlfn.SWITCH(TRUE,F10="T",TEXT($F$1,"00"),AND(F10="",K10<>"TERMINAL"),"00",TRUE,TEXT(HOUR(F10),"00"))} -> 08 | T10: {=TEXT(_xlfn.SWITCH(TRUE,F10="T","00",AND(F10="",K10<>"TERMINAL"),"00",TRUE,MINUTE(F10)),"00")} -> 19 | U10: {=TEXT(_xlfn.SWITCH(TRUE,F10="T","00",AND(F10="",K10<>"TERMINAL"),"00",TRUE,SECOND(F10)),"00")} -> 45 | V10: =IF(AND(S10="00",F9<>"t",V9<>"00"),"24",S10) -> 08 | W10: {=_xlfn.SWITCH(TRUE,OR(S10=TEXT($B$1,"00"),S10=TEXT($D$1,"00")),"00",AND(T10="00",K10<>"TERMINAL"),TEXT($D$2,"00"),TRUE,T10)} -> 19 | X10: {=_xlfn.SWITCH(TRUE,OR(S10=TEXT($B$1,"00"),S10=TEXT($D$1,"00")),"00",AND(U10="00",K10<>"TERMINAL"),TEXT($F$2,"00"),TRUE,U10)} -> 45 | Y10: =IF(OR(S10="27"),S9,S10) -> 08 | Z10: =IF(OR(Y10>R10,R10>Y9),"TRUE","FALSE") -> FALSE | AA10: =IF(Z10="TRUE",O10&P10&Q10,IF(OR(L10="25",L10="26"),O10&P10&Q10,"00"&P10&Q10)) -> 250000 | AB10: =IF(Z10="TRUE",V10&W10&X10,IF(S10="27",V10&W10&X10,"00"&W10&X10)) -> 001945 | AC10: {=TEXT($D10,"000")&TEXT(IFERROR(INDEX($D$5:$D$103,_xlfn.AGGREGATE(15,6,ROW($E$5:$E$103)/(($E$5:$E$103<>"p")*($E$5:$E$103<>"t")*(ROW($E$5:$E$103)>ROW($E10))),1)-ROW($E$5)+1),$D10),"000")} -> 067069 | AD10: {=TEXT(_xlfn.XLOOKUP(TRUE, AA11:AA$103<>"250000", AA11:AA$103, "未找到"),"000000")} -> 002260 | AE10: {=_xlfn.SWITCH(TRUE,J10<>"",TEXT(J10,"MMSS"),TRUE,IFERROR(TEXT(E11-F10,"MMSS"),"0000"))} -> 0215
A11: 8 | B11: 大 宮 | C11: 30560 | D11: 69 | E11: 0.34861111 | F11: 0.34930556 | H11: 45 | J11: =F12-F11 -> 0.0019097222 | K11: =IF(E10="着(hh:mm:ss)","start",IF(E11="p","pass",IF(OR(F11="t",K10="terminal"),"terminal","stop"))) -> stop | L11: {=TEXT(_xlfn.SWITCH(TRUE,E11="P",$B$1,AND(E11="",K11<>"TERMINAL"),$D$1,TRUE,HOUR(E11)),"00")} -> 08 | M11: {=TEXT(_xlfn.SWITCH(TRUE,E11="P","00",AND(E11="",K11<>"TERMINAL"),"00",TRUE,MINUTE(E11)),"00")} -> 22 | N11: {=TEXT(_xlfn.SWITCH(TRUE,E11="P","00",AND(E11="",K11<>"TERMINAL"),"00",TRUE,SECOND(E11)),"00")} -> 00 | O11: {=_xlfn.SWITCH(TRUE,AND(L11="00",K11<>"TERMINAL"),TEXT($B$2,"00"),L11=TEXT($B$1,"00"),TEXT($B$1,"00"),L11=TEXT($D$1,"00"),TEXT($D$1,"00"),TRUE,+L11)} -> 08 | P11: {=_xlfn.SWITCH(TRUE,OR(L11=TEXT($B$1,"00"),L11=TEXT($D$1,"00")),"00",AND(M11="00",K11<>"TERMINAL"),TEXT($D$2,"00"),TRUE,M11)} -> 22 | Q11: {=_xlfn.SWITCH(TRUE,OR(L11=TEXT($B$1,"00"),L11=TEXT($D$1,"00")),"00",AND(N11="00",K11<>"TERMINAL"),TEXT($F$2,"00"),TRUE,N11)} -> 60 | R11: =IF(OR(L11="25",L11="26"),TEXT(MAX(VALUE(R10),VALUE(Y10)),"00"),L11) -> 08 | S11: {=_xlfn.SWITCH(TRUE,F11="T",TEXT($F$1,"00"),AND(F11="",K11<>"TERMINAL"),"00",TRUE,TEXT(HOUR(F11),"00"))} -> 08 | T11: {=TEXT(_xlfn.SWITCH(TRUE,F11="T","00",AND(F11="",K11<>"TERMINAL"),"00",TRUE,MINUTE(F11)),"00")} -> 23 | U11: {=TEXT(_xlfn.SWITCH(TRUE,F11="T","00",AND(F11="",K11<>"TERMINAL"),"00",TRUE,SECOND(F11)),"00")} -> 00 | V11: =IF(AND(S11="00",F10<>"t",V10<>"00"),"24",S11) -> 08 | W11: {=_xlfn.SWITCH(TRUE,OR(S11=TEXT($B$1,"00"),S11=TEXT($D$1,"00")),"00",AND(T11="00",K11<>"TERMINAL"),TEXT($D$2,"00"),TRUE,T11)} -> 23 | X11: {=_xlfn.SWITCH(TRUE,OR(S11=TEXT($B$1,"00"),S11=TEXT($D$1,"00")),"00",AND(U11="00",K11<>"TERMINAL"),TEXT($F$2,"00"),TRUE,U11)} -> 60 | Y11: =IF(OR(S11="27"),S10,S11) -> 08 | Z11: =IF(OR(Y11>R11,R11>Y10),"TRUE","FALSE") -> FALSE | AA11: =IF(Z11="TRUE",O11&P11&Q11,IF(OR(L11="25",L11="26"),O11&P11&Q11,"00"&P11&Q11)) -> 002260 | AB11: =IF(Z11="TRUE",V11&W11&X11,IF(S11="27",V11&W11&X11,"00"&W11&X11)) -> 002360 | AC11: {=TEXT($D11,"000")&TEXT(IFERROR(INDEX($D$5:$D$103,_xlfn.AGGREGATE(15,6,ROW($E$5:$E$103)/(($E$5:$E$103<>"p")*($E$5:$E$103<>"t")*(ROW($E$5:$E$103)>ROW($E11))),1)-ROW($E$5)+1),$D11),"000")} -> 069073 | AD11: {=TEXT(_xlfn.XLOOKUP(TRUE, AA12:AA$103<>"250000", AA12:AA$103, "未找到"),"000000")} -> 002945 | AE11: {=_xlfn.SWITCH(TRUE,J11<>"",TEXT(J11,"MMSS"),TRUE,IFERROR(TEXT(E12-F11,"MMSS"),"0000"))} -> 0245
A12: 9 | B12: 土 呂 | C12: 33570 | D12: 70 | E12: p | F12: 0.35121528 | J12: =F13-F12 -> 0.0010416667 | K12: =IF(E11="着(hh:mm:ss)","start",IF(E12="p","pass",IF(OR(F12="t",K11="terminal"),"terminal","stop"))) -> pass | L12: {=TEXT(_xlfn.SWITCH(TRUE,E12="P",$B$1,AND(E12="",K12<>"TERMINAL"),$D$1,TRUE,HOUR(E12)),"00")} -> 25 | M12: {=TEXT(_xlfn.SWITCH(TRUE,E12="P","00",AND(E12="",K12<>"TERMINAL"),"00",TRUE,MINUTE(E12)),"00")} -> 00 | N12: {=TEXT(_xlfn.SWITCH(TRUE,E12="P","00",AND(E12="",K12<>"TERMINAL"),"00",TRUE,SECOND(E12)),"00")} -> 00 | O12: {=_xlfn.SWITCH(TRUE,AND(L12="00",K12<>"TERMINAL"),TEXT($B$2,"00"),L12=TEXT($B$1,"00"),TEXT($B$1,"00"),L12=TEXT($D$1,"00"),TEXT($D$1,"00"),TRUE,+L12)} -> 25 | P12: {=_xlfn.SWITCH(TRUE,OR(L12=TEXT($B$1,"00"),L12=TEXT($D$1,"00")),"00",AND(M12="00",K12<>"TERMINAL"),TEXT($D$2,"00"),TRUE,M12)} -> 00 | Q12: {=_xlfn.SWITCH(TRUE,OR(L12=TEXT($B$1,"00"),L12=TEXT($D$1,"00")),"00",AND(N12="00",K12<>"TERMINAL"),TEXT($F$2,"00"),TRUE,N12)} -> 00 | R12: =IF(OR(L12="25",L12="26"),TEXT(MAX(VALUE(R11),VALUE(Y11)),"00"),L12) -> 08 | S12: {=_xlfn.SWITCH(TRUE,F12="T",TEXT($F$1,"00"),AND(F12="",K12<>"TERMINAL"),"00",TRUE,TEXT(HOUR(F12),"00"))} -> 08 | T12: {=TEXT(_xlfn.SWITCH(TRUE,F12="T","00",AND(F12="",K12<>"TERMINAL"),"00",TRUE,MINUTE(F12)),"00")} -> 25 | U12: {=TEXT(_xlfn.SWITCH(TRUE,F12="T","00",AND(F12="",K12<>"TERMINAL"),"00",TRUE,SECOND(F12)),"00")} -> 45 | V12: =IF(AND(S12="00",F11<>"t",V11<>"00"),"24",S12) -> 08 | W12: {=_xlfn.SWITCH(TRUE,OR(S12=TEXT($B$1,"00"),S12=TEXT($D$1,"00")),"00",AND(T12="00",K12<>"TERMINAL"),TEXT($D$2,"00"),TRUE,T12)} -> 25 | X12: {=_xlfn.SWITCH(TRUE,OR(S12=TEXT($B$1,"00"),S12=TEXT($D$1,"00")),"00",AND(U12="00",K12<>"TERMINAL"),TEXT($F$2,"00"),TRUE,U12)} -> 45 | Y12: =IF(OR(S12="27"),S11,S12) -> 08 | Z12: =IF(OR(Y12>R12,R12>Y11),"TRUE","FALSE") -> FALSE | AA12: =IF(Z12="TRUE",O12&P12&Q12,IF(OR(L12="25",L12="26"),O12&P12&Q12,"00"&P12&Q12)) -> 250000 | AB12: =IF(Z12="TRUE",V12&W12&X12,IF(S12="27",V12&W12&X12,"00"&W12&X12)) -> 002545 | AC12: {=TEXT($D12,"000")&TEXT(IFERROR(INDEX($D$5:$D$103,_xlfn.AGGREGATE(15,6,ROW($E$5:$E$103)/(($E$5:$E$103<>"p")*($E$5:$E$103<>"t")*(ROW($E$5:$E$103)>ROW($E12))),1)-ROW($E$5)+1),$D12),"000")} -> 070073 | AD12: {=TEXT(_xlfn.XLOOKUP(TRUE, AA13:AA$103<>"250000", AA13:AA$103, "未找到"),"000000")} -> 002945 | AE12: {=_xlfn.SWITCH(TRUE,J12<>"",TEXT(J12,"MMSS"),TRUE,IFERROR(TEXT(E13-F12,"MMSS"),"0000"))} -> 0130
A13: 10 | B13: 東 大 宮 | C13: 35668 | D13: 72 | E13: p | F13: 0.35225694 | K13: =IF(E12="着(hh:mm:ss)","start",IF(E13="p","pass",IF(OR(F13="t",K12="terminal"),"terminal","stop"))) -> pass | L13: {=TEXT(_xlfn.SWITCH(TRUE,E13="P",$B$1,AND(E13="",K13<>"TERMINAL"),$D$1,TRUE,HOUR(E13)),"00")} -> 25 | M13: {=TEXT(_xlfn.SWITCH(TRUE,E13="P","00",AND(E13="",K13<>"TERMINAL"),"00",TRUE,MINUTE(E13)),"00")} -> 00 | N13: {=TEXT(_xlfn.SWITCH(TRUE,E13="P","00",AND(E13="",K13<>"TERMINAL"),"00",TRUE,SECOND(E13)),"00")} -> 00 | O13: {=_xlfn.SWITCH(TRUE,AND(L13="00",K13<>"TERMINAL"),TEXT($B$2,"00"),L13=TEXT($B$1,"00"),TEXT($B$1,"00"),L13=TEXT($D$1,"00"),TEXT($D$1,"00"),TRUE,+L13)} -> 25 | P13: {=_xlfn.SWITCH(TRUE,OR(L13=TEXT($B$1,"00"),L13=TEXT($D$1,"00")),"00",AND(M13="00",K13<>"TERMINAL"),TEXT($D$2,"00"),TRUE,M13)} -> 00 | Q13: {=_xlfn.SWITCH(TRUE,OR(L13=TEXT($B$1,"00"),L13=TEXT($D$1,"00")),"00",AND(N13="00",K13<>"TERMINAL"),TEXT($F$2,"00"),TRUE,N13)} -> 00 | R13: =IF(OR(L13="25",L13="26"),TEXT(MAX(VALUE(R12),VALUE(Y12)),"00"),L13) -> 08 | S13: {=_xlfn.SWITCH(TRUE,F13="T",TEXT($F$1,"00"),AND(F13="",K13<>"TERMINAL"),"00",TRUE,TEXT(HOUR(F13),"00"))} -> 08 | T13: {=TEXT(_xlfn.SWITCH(TRUE,F13="T","00",AND(F13="",K13<>"TERMINAL"),"00",TRUE,MINUTE(F13)),"00")} -> 27 | U13: {=TEXT(_xlfn.SWITCH(TRUE,F13="T","00",AND(F13="",K13<>"TERMINAL"),"00",TRUE,SECOND(F13)),"00")} -> 15 | V13: =IF(AND(S13="00",F12<>"t",V12<>"00"),"24",S13) -> 08 | W13: {=_xlfn.SWITCH(TRUE,OR(S13=TEXT($B$1,"00"),S13=TEXT($D$1,"00")),"00",AND(T13="00",K13<>"TERMINAL"),TEXT($D$2,"00"),TRUE,T13)} -> 27 | X13: {=_xlfn.SWITCH(TRUE,OR(S13=TEXT($B$1,"00"),S13=TEXT($D$1,"00")),"00",AND(U13="00",K13<>"TERMINAL"),TEXT($F$2,"00"),TRUE,U13)} -> 15 | Y13: =IF(OR(S13="27"),S12,S13) -> 08 | Z13: =IF(OR(Y13>R13,R13>Y12),"TRUE","FALSE") -> FALSE | AA13: =IF(Z13="TRUE",O13&P13&Q13,IF(OR(L13="25",L13="26"),O13&P13&Q13,"00"&P13&Q13)) -> 250000 | AB13: =IF(Z13="TRUE",V13&W13&X13,IF(S13="27",V13&W13&X13,"00"&W13&X13)) -> 002715 | AC13: {=TEXT($D13,"000")&TEXT(IFERROR(INDEX($D$5:$D$103,_xlfn.AGGREGATE(15,6,ROW($E$5:$E$103)/(($E$5:$E$103<>"p")*($E$5:$E$103<>"t")*(ROW($E$5:$E$103)>ROW($E13))),1)-ROW($E$5)+1),$D13),"000")} -> 072073 | AD13: {=TEXT(_xlfn.XLOOKUP(TRUE, AA14:AA$103<>"250000", AA14:AA$103, "未找到"),"000000")} -> 002945 | AE13: {=_xlfn.SWITCH(TRUE,J13<>"",TEXT(J13,"MMSS"),TRUE,IFERROR(TEXT(E14-F13,"MMSS"),"0000"))} -> 0230
A14: 11 | B14: 蓮 田 | C14: 39538 | D14: 73 | E14: 0.35399306 | F14: 0.35434028 | J14: =F15-F14 -> 0.0020833333 | K14: =IF(E13="着(hh:mm:ss)","start",IF(E14="p","pass",IF(OR(F14="t",K13="terminal"),"terminal","stop"))) -> stop | L14: {=TEXT(_xlfn.SWITCH(TRUE,E14="P",$B$1,AND(E14="",K14<>"TERMINAL"),$D$1,TRUE,HOUR(E14)),"00")} -> 08 | M14: {=TEXT(_xlfn.SWITCH(TRUE,E14="P","00",AND(E14="",K14<>"TERMINAL"),"00",TRUE,MINUTE(E14)),"00")} -> 29 | N14: {=TEXT(_xlfn.SWITCH(TRUE,E14="P","00",AND(E14="",K14<>"TERMINAL"),"00",TRUE,SECOND(E14)),"00")} -> 45 | O14: {=_xlfn.SWITCH(TRUE,AND(L14="00",K14<>"TERMINAL"),TEXT($B$2,"00"),L14=TEXT($B$1,"00"),TEXT($B$1,"00"),L14=TEXT($D$1,"00"),TEXT($D$1,"00"),TRUE,+L14)} -> 08 | P14: {=_xlfn.SWITCH(TRUE,OR(L14=TEXT($B$1,"00"),L14=TEXT($D$1,"00")),"00",AND(M14="00",K14<>"TERMINAL"),TEXT($D$2,"00"),TRUE,M14)} -> 29 | Q14: {=_xlfn.SWITCH(TRUE,OR(L14=TEXT($B$1,"00"),L14=TEXT($D$1,"00")),"00",AND(N14="00",K14<>"TERMINAL"),TEXT($F$2,"00"),TRUE,N14)} -> 45 | R14: =IF(OR(L14="25",L14="26"),TEXT(MAX(VALUE(R13),VALUE(Y13)),"00"),L14) -> 08 | S14: {=_xlfn.SWITCH(TRUE,F14="T",TEXT($F$1,"00"),AND(F14="",K14<>"TERMINAL"),"00",TRUE,TEXT(HOUR(F14),"00"))} -> 08 | T14: {=TEXT(_xlfn.SWITCH(TRUE,F14="T","00",AND(F14="",K14<>"TERMINAL"),"00",TRUE,MINUTE(F14)),"00")} -> 30 | U14: {=TEXT(_xlfn.SWITCH(TRUE,F14="T","00",AND(F14="",K14<>"TERMINAL"),"00",TRUE,SECOND(F14)),"00")} -> 15 | V14: =IF(AND(S14="00",F13<>"t",V13<>"00"),"24",S14) -> 08 | W14: {=_xlfn.SWITCH(TRUE,OR(S14=TEXT($B$1,"00"),S14=TEXT($D$1,"00")),"00",AND(T14="00",K14<>"TERMINAL"),TEXT($D$2,"00"),TRUE,T14)} -> 30 | X14: {=_xlfn.SWITCH(TRUE,OR(S14=TEXT($B$1,"00"),S14=TEXT($D$1,"00")),"00",AND(U14="00",K14<>"TERMINAL"),TEXT($F$2,"00"),TRUE,U14)} -> 15 | Y14: =IF(OR(S14="27"),S13,S14) -> 08 | Z14: =IF(OR(Y14>R14,R14>Y13),"TRUE","FALSE") -> FALSE | AA14: =IF(Z14="TRUE",O14&P14&Q14,IF(OR(L14="25",L14="26"),O14&P14&Q14,"00"&P14&Q14)) -> 002945 | AB14: =IF(Z14="TRUE",V14&W14&X14,IF(S14="27",V14&W14&X14,"00"&W14&X14)) -> 003015 | AC14: {=TEXT($D14,"000")&TEXT(IFERROR(INDEX($D$5:$D$103,_xlfn.AGGREGATE(15,6,ROW($E$5:$E$103)/(($E$5:$E$103<>"p")*($E$5:$E$103<>"t")*(ROW($E$5:$E$103)>ROW($E14))),1)-ROW($E$5)+1),$D14),"000")} -> 073076 | AD14: {=TEXT(_xlfn.XLOOKUP(TRUE, AA15:AA$103<>"250000", AA15:AA$103, "未找到"),"000000")} -> 003760 | AE14: {=_xlfn.SWITCH(TRUE,J14<>"",TEXT(J14,"MMSS"),TRUE,IFERROR(TEXT(E15-F14,"MMSS"),"0000"))} -> 0300
A15: 12 | B15: 白 岡 | C15: 43818 | D15: 74 | E15: p | F15: 0.35642361 | J15: =F16-F15 -> 0.0010416667 | K15: =IF(E14="着(hh:mm:ss)","start",IF(E15="p","pass",IF(OR(F15="t",K14="terminal"),"terminal","stop"))) -> pass | L15: {=TEXT(_xlfn.SWITCH(TRUE,E15="P",$B$1,AND(E15="",K15<>"TERMINAL"),$D$1,TRUE,HOUR(E15)),"00")} -> 25 | M15: {=TEXT(_xlfn.SWITCH(TRUE,E15="P","00",AND(E15="",K15<>"TERMINAL"),"00",TRUE,MINUTE(E15)),"00")} -> 00 | N15: {=TEXT(_xlfn.SWITCH(TRUE,E15="P","00",AND(E15="",K15<>"TERMINAL"),"00",TRUE,SECOND(E15)),"00")} -> 00 | O15: {=_xlfn.SWITCH(TRUE,AND(L15="00",K15<>"TERMINAL"),TEXT($B$2,"00"),L15=TEXT($B$1,"00"),TEXT($B$1,"00"),L15=TEXT($D$1,"00"),TEXT($D$1,"00"),TRUE,+L15)} -> 25 | P15: {=_xlfn.SWITCH(TRUE,OR(L15=TEXT($B$1,"00"),L15=TEXT($D$1,"00")),"00",AND(M15="00",K15<>"TERMINAL"),TEXT($D$2,"00"),TRUE,M15)} -> 00 | Q15: {=_xlfn.SWITCH(TRUE,OR(L15=TEXT($B$1,"00"),L15=TEXT($D$1,"00")),"00",AND(N15="00",K15<>"TERMINAL"),TEXT($F$2,"00"),TRUE,N15)} -> 00 | R15: =IF(OR(L15="25",L15="26"),TEXT(MAX(VALUE(R14),VALUE(Y14)),"00"),L15) -> 08 | S15: {=_xlfn.SWITCH(TRUE,F15="T",TEXT($F$1,"00"),AND(F15="",K15<>"TERMINAL"),"00",TRUE,TEXT(HOUR(F15),"00"))} -> 08 | T15: {=TEXT(_xlfn.SWITCH(TRUE,F15="T","00",AND(F15="",K15<>"TERMINAL"),"00",TRUE,MINUTE(F15)),"00")} -> 33 | U15: {=TEXT(_xlfn.SWITCH(TRUE,F15="T","00",AND(F15="",K15<>"TERMINAL"),"00",TRUE,SECOND(F15)),"00")} -> 15 | V15: =IF(AND(S15="00",F14<>"t",V14<>"00"),"24",S15) -> 08 | W15: {=_xlfn.SWITCH(TRUE,OR(S15=TEXT($B$1,"00"),S15=TEXT($D$1,"00")),"00",AND(T15="00",K15<>"TERMINAL"),TEXT($D$2,"00"),TRUE,T15)} -> 33 | X15: {=_xlfn.SWITCH(TRUE,OR(S15=TEXT($B$1,"00"),S15=TEXT($D$1,"00")),"00",AND(U15="00",K15<>"TERMINAL"),TEXT($F$2,"00"),TRUE,U15)} -> 15 | Y15: =IF(OR(S15="27"),S14,S15) -> 08 | Z15: =IF(OR(Y15>R15,R15>Y14),"TRUE","FALSE") -> FALSE | AA15: =IF(Z15="TRUE",O15&P15&Q15,IF(OR(L15="25",L15="26"),O15&P15&Q15,"00"&P15&Q15)) -> 250000 | AB15: =IF(Z15="TRUE",V15&W15&X15,IF(S15="27",V15&W15&X15,"00"&W15&X15)) -> 003315 | AC15: {=TEXT($D15,"000")&TEXT(IFERROR(INDEX($D$5:$D$103,_xlfn.AGGREGATE(15,6,ROW($E$5:$E$103)/(($E$5:$E$103<>"p")*($E$5:$E$103<>"t")*(ROW($E$5:$E$103)>ROW($E15))),1)-ROW($E$5)+1),$D15),"000")} -> 074076 | AD15: {=TEXT(_xlfn.XLOOKUP(TRUE, AA16:AA$103<>"250000", AA16:AA$103, "未找到"),"000000")} -> 003760 | AE15: {=_xlfn.SWITCH(TRUE,J15<>"",TEXT(J15,"MMSS"),TRUE,IFERROR(TEXT(E16-F15,"MMSS"),"0000"))} -> 0130
A16: 13 | B16: 新 白 岡 | C16: 46196 | D16: 75 | E16: p | F16: 0.35746528 | K16: =IF(E15="着(hh:mm:ss)","start",IF(E16="p","pass",IF(OR(F16="t",K15="terminal"),"terminal","stop"))) -> pass | L16: {=TEXT(_xlfn.SWITCH(TRUE,E16="P",$B$1,AND(E16="",K16<>"TERMINAL"),$D$1,TRUE,HOUR(E16)),"00")} -> 25 | M16: {=TEXT(_xlfn.SWITCH(TRUE,E16="P","00",AND(E16="",K16<>"TERMINAL"),"00",TRUE,MINUTE(E16)),"00")} -> 00 | N16: {=TEXT(_xlfn.SWITCH(TRUE,E16="P","00",AND(E16="",K16<>"TERMINAL"),"00",TRUE,SECOND(E16)),"00")} -> 00 | O16: {=_xlfn.SWITCH(TRUE,AND(L16="00",K16<>"TERMINAL"),TEXT($B$2,"00"),L16=TEXT($B$1,"00"),TEXT($B$1,"00"),L16=TEXT($D$1,"00"),TEXT($D$1,"00"),TRUE,+L16)} -> 25 | P16: {=_xlfn.SWITCH(TRUE,OR(L16=TEXT($B$1,"00"),L16=TEXT($D$1,"00")),"00",AND(M16="00",K16<>"TERMINAL"),TEXT($D$2,"00"),TRUE,M16)} -> 00 | Q16: {=_xlfn.SWITCH(TRUE,OR(L16=TEXT($B$1,"00"),L16=TEXT($D$1,"00")),"00",AND(N16="00",K16<>"TERMINAL"),TEXT($F$2,"00"),TRUE,N16)} -> 00 | R16: =IF(OR(L16="25",L16="26"),TEXT(MAX(VALUE(R15),VALUE(Y15)),"00"),L16) -> 08 | S16: {=_xlfn.SWITCH(TRUE,F16="T",TEXT($F$1,"00"),AND(F16="",K16<>"TERMINAL"),"00",TRUE,TEXT(HOUR(F16),"00"))} -> 08 | T16: {=TEXT(_xlfn.SWITCH(TRUE,F16="T","00",AND(F16="",K16<>"TERMINAL"),"00",TRUE,MINUTE(F16)),"00")} -> 34 | U16: {=TEXT(_xlfn.SWITCH(TRUE,F16="T","00",AND(F16="",K16<>"TERMINAL"),"00",TRUE,SECOND(F16)),"00")} -> 45 | V16: =IF(AND(S16="00",F15<>"t",V15<>"00"),"24",S16) -> 08 | W16: {=_xlfn.SWITCH(TRUE,OR(S16=TEXT($B$1,"00"),S16=TEXT($D$1,"00")),"00",AND(T16="00",K16<>"TERMINAL"),TEXT($D$2,"00"),TRUE,T16)} -> 34 | X16: {=_xlfn.SWITCH(TRUE,OR(S16=TEXT($B$1,"00"),S16=TEXT($D$1,"00")),"00",AND(U16="00",K16<>"TERMINAL"),TEXT($F$2,"00"),TRUE,U16)} -> 45 | Y16: =IF(OR(S16="27"),S15,S16) -> 08 | Z16: =IF(OR(Y16>R16,R16>Y15),"TRUE","FALSE") -> FALSE | AA16: =IF(Z16="TRUE",O16&P16&Q16,IF(OR(L16="25",L16="26"),O16&P16&Q16,"00"&P16&Q16)) -> 250000 | AB16: =IF(Z16="TRUE",V16&W16&X16,IF(S16="27",V16&W16&X16,"00"&W16&X16)) -> 003445 | AC16: {=TEXT($D16,"000")&TEXT(IFERROR(INDEX($D$5:$D$103,_xlfn.AGGREGATE(15,6,ROW($E$5:$E$103)/(($E$5:$E$103<>"p")*($E$5:$E$103<>"t")*(ROW($E$5:$E$103)>ROW($E16))),1)-ROW($E$5)+1),$D16),"000")} -> 075076 | AD16: {=TEXT(_xlfn.XLOOKUP(TRUE, AA17:AA$103<>"250000", AA17:AA$103, "未找到"),"000000")} -> 003760 | AE16: {=_xlfn.SWITCH(TRUE,J16<>"",TEXT(J16,"MMSS"),TRUE,IFERROR(TEXT(E17-F16,"MMSS"),"0000"))} -> 0215
A17: 14 | B17: 久 喜 | C17: 49193 | D17: 76 | E17: 0.35902778 | F17: 0.359375 | H17: 85 | I17: 85 | J17: =F18-F17 -> 0.0017361111 | K17: =IF(E16="着(hh:mm:ss)","start",IF(E17="p","pass",IF(OR(F17="t",K16="terminal"),"terminal","stop"))) -> stop | L17: {=TEXT(_xlfn.SWITCH(TRUE,E17="P",$B$1,AND(E17="",K17<>"TERMINAL"),$D$1,TRUE,HOUR(E17)),"00")} -> 08 | M17: {=TEXT(_xlfn.SWITCH(TRUE,E17="P","00",AND(E17="",K17<>"TERMINAL"),"00",TRUE,MINUTE(E17)),"00")} -> 37 | N17: {=TEXT(_xlfn.SWITCH(TRUE,E17="P","00",AND(E17="",K17<>"TERMINAL"),"00",TRUE,SECOND(E17)),"00")} -> 00 | O17: {=_xlfn.SWITCH(TRUE,AND(L17="00",K17<>"TERMINAL"),TEXT($B$2,"00"),L17=TEXT($B$1,"00"),TEXT($B$1,"00"),L17=TEXT($D$1,"00"),TEXT($D$1,"00"),TRUE,+L17)} -> 08 | P17: {=_xlfn.SWITCH(TRUE,OR(L17=TEXT($B$1,"00"),L17=TEXT($D$1,"00")),"00",AND(M17="00",K17<>"TERMINAL"),TEXT($D$2,"00"),TRUE,M17)} -> 37 | Q17: {=_xlfn.SWITCH(TRUE,OR(L17=TEXT($B$1,"00"),L17=TEXT($D$1,"00")),"00",AND(N17="00",K17<>"TERMINAL"),TEXT($F$2,"00"),TRUE,N17)} -> 60 | R17: =IF(OR(L17="25",L17="26"),TEXT(MAX(VALUE(R16),VALUE(Y16)),"00"),L17) -> 08 | S17: {=_xlfn.SWITCH(TRUE,F17="T",TEXT($F$1,"00"),AND(F17="",K17<>"TERMINAL"),"00",TRUE,TEXT(HOUR(F17),"00"))} -> 08 | T17: {=TEXT(_xlfn.SWITCH(TRUE,F17="T","00",AND(F17="",K17<>"TERMINAL"),"00",TRUE,MINUTE(F17)),"00")} -> 37 | U17: {=TEXT(_xlfn.SWITCH(TRUE,F17="T","00",AND(F17="",K17<>"TERMINAL"),"00",TRUE,SECOND(F17)),"00")} -> 30 | V17: =IF(AND(S17="00",F16<>"t",V16<>"00"),"24",S17) -> 08 | W17: {=_xlfn.SWITCH(TRUE,OR(S17=TEXT($B$1,"00"),S17=TEXT($D$1,"00")),"00",AND(T17="00",K17<>"TERMINAL"),TEXT($D$2,"00"),TRUE,T17)} -> 37 | X17: {=_xlfn.SWITCH(TRUE,OR(S17=TEXT($B$1,"00"),S17=TEXT($D$1,"00")),"00",AND(U17="00",K17<>"TERMINAL"),TEXT($F$2,"00"),TRUE,U17)} -> 30 | Y17: =IF(OR(S17="27"),S16,S17) -> 08 | Z17: =IF(OR(Y17>R17,R17>Y16),"TRUE","FALSE") -> FALSE | AA17: =IF(Z17="TRUE",O17&P17&Q17,IF(OR(L17="25",L17="26"),O17&P17&Q17,"00"&P17&Q17)) -> 003760 | AB17: =IF(Z17="TRUE",V17&W17&X17,IF(S17="27",V17&W17&X17,"00"&W17&X17)) -> 003730 | AC17: {=TEXT($D17,"000")&TEXT(IFERROR(INDEX($D$5:$D$103,_xlfn.AGGREGATE(15,6,ROW($E$5:$E$103)/(($E$5:$E$103<>"p")*($E$5:$E$103<>"t")*(ROW($E$5:$E$103)>ROW($E17))),1)-ROW($E$5)+1),$D17),"000")} -> 076079 | AD17: {=TEXT(_xlfn.XLOOKUP(TRUE, AA18:AA$103<>"250000", AA18:AA$103, "未找到"),"000000")} -> 004960 | AE17: {=_xlfn.SWITCH(TRUE,J17<>"",TEXT(J17,"MMSS"),TRUE,IFERROR(TEXT(E18-F17,"MMSS"),"0000"))} -> 0230
A18: 15 | B18: 東 鷲 宮 | C18: 51971 | D18: 77 | E18: p | F18: 0.36111111 | J18: =F19-F18 -> 0.0027777778 | K18: =IF(E17="着(hh:mm:ss)","start",IF(E18="p","pass",IF(OR(F18="t",K17="terminal"),"terminal","stop"))) -> pass | L18: {=TEXT(_xlfn.SWITCH(TRUE,E18="P",$B$1,AND(E18="",K18<>"TERMINAL"),$D$1,TRUE,HOUR(E18)),"00")} -> 25 | M18: {=TEXT(_xlfn.SWITCH(TRUE,E18="P","00",AND(E18="",K18<>"TERMINAL"),"00",TRUE,MINUTE(E18)),"00")} -> 00 | N18: {=TEXT(_xlfn.SWITCH(TRUE,E18="P","00",AND(E18="",K18<>"TERMINAL"),"00",TRUE,SECOND(E18)),"00")} -> 00 | O18: {=_xlfn.SWITCH(TRUE,AND(L18="00",K18<>"TERMINAL"),TEXT($B$2,"00"),L18=TEXT($B$1,"00"),TEXT($B$1,"00"),L18=TEXT($D$1,"00"),TEXT($D$1,"00"),TRUE,+L18)} -> 25 | P18: {=_xlfn.SWITCH(TRUE,OR(L18=TEXT($B$1,"00"),L18=TEXT($D$1,"00")),"00",AND(M18="00",K18<>"TERMINAL"),TEXT($D$2,"00"),TRUE,M18)} -> 00 | Q18: {=_xlfn.SWITCH(TRUE,OR(L18=TEXT($B$1,"00"),L18=TEXT($D$1,"00")),"00",AND(N18="00",K18<>"TERMINAL"),TEXT($F$2,"00"),TRUE,N18)} -> 00 | R18: =IF(OR(L18="25",L18="26"),TEXT(MAX(VALUE(R17),VALUE(Y17)),"00"),L18) -> 08 | S18: {=_xlfn.SWITCH(TRUE,F18="T",TEXT($F$1,"00"),AND(F18="",K18<>"TERMINAL"),"00",TRUE,TEXT(HOUR(F18),"00"))} -> 08 | T18: {=TEXT(_xlfn.SWITCH(TRUE,F18="T","00",AND(F18="",K18<>"TERMINAL"),"00",TRUE,MINUTE(F18)),"00")} -> 40 | U18: {=TEXT(_xlfn.SWITCH(TRUE,F18="T","00",AND(F18="",K18<>"TERMINAL"),"00",TRUE,SECOND(F18)),"00")} -> 00 | V18: =IF(AND(S18="00",F17<>"t",V17<>"00"),"24",S18) -> 08 | W18: {=_xlfn.SWITCH(TRUE,OR(S18=TEXT($B$1,"00"),S18=TEXT($D$1,"00")),"00",AND(T18="00",K18<>"TERMINAL"),TEXT($D$2,"00"),TRUE,T18)} -> 40 | X18: {=_xlfn.SWITCH(TRUE,OR(S18=TEXT($B$1,"00"),S18=TEXT($D$1,"00")),"00",AND(U18="00",K18<>"TERMINAL"),TEXT($F$2,"00"),TRUE,U18)} -> 60 | Y18: =IF(OR(S18="27"),S17,S18) -> 08 | Z18: =IF(OR(Y18>R18,R18>Y17),"TRUE","FALSE") -> FALSE | AA18: =IF(Z18="TRUE",O18&P18&Q18,IF(OR(L18="25",L18="26"),O18&P18&Q18,"00"&P18&Q18)) -> 250000 | AB18: =IF(Z18="TRUE",V18&W18&X18,IF(S18="27",V18&W18&X18,"00"&W18&X18)) -> 004060 | AC18: {=TEXT($D18,"000")&TEXT(IFERROR(INDEX($D$5:$D$103,_xlfn.AGGREGATE(15,6,ROW($E$5:$E$103)/(($E$5:$E$103<>"p")*($E$5:$E$103<>"t")*(ROW($E$5:$E$103)>ROW($E18))),1)-ROW($E$5)+1),$D18),"000")} -> 077079 | AD18: {=TEXT(_xlfn.XLOOKUP(TRUE, AA19:AA$103<>"250000", AA19:AA$103, "未找到"),"000000")} -> 004960 | AE18: {=_xlfn.SWITCH(TRUE,J18<>"",TEXT(J18,"MMSS"),TRUE,IFERROR(TEXT(E19-F18,"MMSS"),"0000"))} -> 0400
A19: 16 | B19: 栗 橋 | C19: 57590 | D19: 78 | E19: p | F19: 0.36388889 | K19: =IF(E18="着(hh:mm:ss)","start",IF(E19="p","pass",IF(OR(F19="t",K18="terminal"),"terminal","stop"))) -> pass | L19: {=TEXT(_xlfn.SWITCH(TRUE,E19="P",$B$1,AND(E19="",K19<>"TERMINAL"),$D$1,TRUE,HOUR(E19)),"00")} -> 25 | M19: {=TEXT(_xlfn.SWITCH(TRUE,E19="P","00",AND(E19="",K19<>"TERMINAL"),"00",TRUE,MINUTE(E19)),"00")} -> 00 | N19: {=TEXT(_xlfn.SWITCH(TRUE,E19="P","00",AND(E19="",K19<>"TERMINAL"),"00",TRUE,SECOND(E19)),"00")} -> 00 | O19: {=_xlfn.SWITCH(TRUE,AND(L19="00",K19<>"TERMINAL"),TEXT($B$2,"00"),L19=TEXT($B$1,"00"),TEXT($B$1,"00"),L19=TEXT($D$1,"00"),TEXT($D$1,"00"),TRUE,+L19)} -> 25 | P19: {=_xlfn.SWITCH(TRUE,OR(L19=TEXT($B$1,"00"),L19=TEXT($D$1,"00")),"00",AND(M19="00",K19<>"TERMINAL"),TEXT($D$2,"00"),TRUE,M19)} -> 00 | Q19: {=_xlfn.SWITCH(TRUE,OR(L19=TEXT($B$1,"00"),L19=TEXT($D$1,"00")),"00",AND(N19="00",K19<>"TERMINAL"),TEXT($F$2,"00"),TRUE,N19)} -> 00 | R19: =IF(OR(L19="25",L19="26"),TEXT(MAX(VALUE(R18),VALUE(Y18)),"00"),L19) -> 08 | S19: {=_xlfn.SWITCH(TRUE,F19="T",TEXT($F$1,"00"),AND(F19="",K19<>"TERMINAL"),"00",TRUE,TEXT(HOUR(F19),"00"))} -> 08 | T19: {=TEXT(_xlfn.SWITCH(TRUE,F19="T","00",AND(F19="",K19<>"TERMINAL"),"00",TRUE,MINUTE(F19)),"00")} -> 44 | U19: {=TEXT(_xlfn.SWITCH(TRUE,F19="T","00",AND(F19="",K19<>"TERMINAL"),"00",TRUE,SECOND(F19)),"00")} -> 00 | V19: =IF(AND(S19="00",F18<>"t",V18<>"00"),"24",S19) -> 08 | W19: {=_xlfn.SWITCH(TRUE,OR(S19=TEXT($B$1,"00"),S19=TEXT($D$1,"00")),"00",AND(T19="00",K19<>"TERMINAL"),TEXT($D$2,"00"),TRUE,T19)} -> 44 | X19: {=_xlfn.SWITCH(TRUE,OR(S19=TEXT($B$1,"00"),S19=TEXT($D$1,"00")),"00",AND(U19="00",K19<>"TERMINAL"),TEXT($F$2,"00"),TRUE,U19)} -> 60 | Y19: =IF(OR(S19="27"),S18,S19) -> 08 | Z19: =IF(OR(Y19>R19,R19>Y18),"TRUE","FALSE") -> FALSE | AA19: =IF(Z19="TRUE",O19&P19&Q19,IF(OR(L19="25",L19="26"),O19&P19&Q19,"00"&P19&Q19)) -> 250000 | AB19: =IF(Z19="TRUE",V19&W19&X19,IF(S19="27",V19&W19&X19,"00"&W19&X19)) -> 004460 | AC19: {=TEXT($D19,"000")&TEXT(IFERROR(INDEX($D$5:$D$103,_xlfn.AGGREGATE(15,6,ROW($E$5:$E$103)/(($E$5:$E$103<>"p")*($E$5:$E$103<>"t")*(ROW($E$5:$E$103)>ROW($E19))),1)-ROW($E$5)+1),$D19),"000")} -> 078079 | AD19: {=TEXT(_xlfn.XLOOKUP(TRUE, AA20:AA$103<>"250000", AA20:AA$103, "未找到"),"000000")} -> 004960 | AE19: {=_xlfn.SWITCH(TRUE,J19<>"",TEXT(J19,"MMSS"),TRUE,IFERROR(TEXT(E20-F19,"MMSS"),"0000"))} -> 0500
A20: 17 | B20: 古 河 | C20: 65015 | D20: 79 | E20: 0.36736111 | F20: 0.36770833 | J20: =F21-F20 -> 0.0022569444 | K20: =IF(E19="着(hh:mm:ss)","start",IF(E20="p","pass",IF(OR(F20="t",K19="terminal"),"terminal","stop"))) -> stop | L20: {=TEXT(_xlfn.SWITCH(TRUE,E20="P",$B$1,AND(E20="",K20<>"TERMINAL"),$D$1,TRUE,HOUR(E20)),"00")} -> 08 | M20: {=TEXT(_xlfn.SWITCH(TRUE,E20="P","00",AND(E20="",K20<>"TERMINAL"),"00",TRUE,MINUTE(E20)),"00")} -> 49 | N20: {=TEXT(_xlfn.SWITCH(TRUE,E20="P","00",AND(E20="",K20<>"TERMINAL"),"00",TRUE,SECOND(E20)),"00")} -> 00 | O20: {=_xlfn.SWITCH(TRUE,AND(L20="00",K20<>"TERMINAL"),TEXT($B$2,"00"),L20=TEXT($B$1,"00"),TEXT($B$1,"00"),L20=TEXT($D$1,"00"),TEXT($D$1,"00"),TRUE,+L20)} -> 08 | P20: {=_xlfn.SWITCH(TRUE,OR(L20=TEXT($B$1,"00"),L20=TEXT($D$1,"00")),"00",AND(M20="00",K20<>"TERMINAL"),TEXT($D$2,"00"),TRUE,M20)} -> 49 | Q20: {=_xlfn.SWITCH(TRUE,OR(L20=TEXT($B$1,"00"),L20=TEXT($D$1,"00")),"00",AND(N20="00",K20<>"TERMINAL"),TEXT($F$2,"00"),TRUE,N20)} -> 60 | R20: =IF(OR(L20="25",L20="26"),TEXT(MAX(VALUE(R19),VALUE(Y19)),"00"),L20) -> 08 | S20: {=_xlfn.SWITCH(TRUE,F20="T",TEXT($F$1,"00"),AND(F20="",K20<>"TERMINAL"),"00",TRUE,TEXT(HOUR(F20),"00"))} -> 08 | T20: {=TEXT(_xlfn.SWITCH(TRUE,F20="T","00",AND(F20="",K20<>"TERMINAL"),"00",TRUE,MINUTE(F20)),"00")} -> 49 | U20: {=TEXT(_xlfn.SWITCH(TRUE,F20="T","00",AND(F20="",K20<>"TERMINAL"),"00",TRUE,SECOND(F20)),"00")} -> 30 | V20: =IF(AND(S20="00",F19<>"t",V19<>"00"),"24",S20) -> 08 | W20: {=_xlfn.SWITCH(TRUE,OR(S20=TEXT($B$1,"00"),S20=TEXT($D$1,"00")),"00",AND(T20="00",K20<>"TERMINAL"),TEXT($D$2,"00"),TRUE,T20)} -> 49 | X20: {=_xlfn.SWITCH(TRUE,OR(S20=TEXT($B$1,"00"),S20=TEXT($D$1,"00")),"00",AND(U20="00",K20<>"TERMINAL"),TEXT($F$2,"00"),TRUE,U20)} -> 30 | Y20: =IF(OR(S20="27"),S19,S20) -> 08 | Z20: =IF(OR(Y20>R20,R20>Y19),"TRUE","FALSE") -> FALSE | AA20: =IF(Z20="TRUE",O20&P20&Q20,IF(OR(L20="25",L20="26"),O20&P20&Q20,"00"&P20&Q20)) -> 004960 | AB20: =IF(Z20="TRUE",V20&W20&X20,IF(S20="27",V20&W20&X20,"00"&W20&X20)) -> 004930 | AC20: {=TEXT($D20,"000")&TEXT(IFERROR(INDEX($D$5:$D$103,_xlfn.AGGREGATE(15,6,ROW($E$5:$E$103)/(($E$5:$E$103<>"p")*($E$5:$E$103<>"t")*(ROW($E$5:$E$103)>ROW($E20))),1)-ROW($E$5)+1),$D20),"000")} -> 079082 | AD20: {=TEXT(_xlfn.XLOOKUP(TRUE, AA21:AA$103<>"250000", AA21:AA$103, "未找到"),"000000")} -> 096015 | AE20: {=_xlfn.SWITCH(TRUE,J20<>"",TEXT(J20,"MMSS"),TRUE,IFERROR(TEXT(E21-F20,"MMSS"),"0000"))} -> 0315
A21: 18 | B21: 野 木 | C21: 69762 | D21: 80 | E21: p | F21: 0.36996528 | J21: =F22-F21 -> 0.0015625 | K21: =IF(E20="着(hh:mm:ss)","start",IF(E21="p","pass",IF(OR(F21="t",K20="terminal"),"terminal","stop"))) -> pass | L21: {=TEXT(_xlfn.SWITCH(TRUE,E21="P",$B$1,AND(E21="",K21<>"TERMINAL"),$D$1,TRUE,HOUR(E21)),"00")} -> 25 | M21: {=TEXT(_xlfn.SWITCH(TRUE,E21="P","00",AND(E21="",K21<>"TERMINAL"),"00",TRUE,MINUTE(E21)),"00")} -> 00 | N21: {=TEXT(_xlfn.SWITCH(TRUE,E21="P","00",AND(E21="",K21<>"TERMINAL"),"00",TRUE,SECOND(E21)),"00")} -> 00 | O21: {=_xlfn.SWITCH(TRUE,AND(L21="00",K21<>"TERMINAL"),TEXT($B$2,"00"),L21=TEXT($B$1,"00"),TEXT($B$1,"00"),L21=TEXT($D$1,"00"),TEXT($D$1,"00"),TRUE,+L21)} -> 25 | P21: {=_xlfn.SWITCH(TRUE,OR(L21=TEXT($B$1,"00"),L21=TEXT($D$1,"00")),"00",AND(M21="00",K21<>"TERMINAL"),TEXT($D$2,"00"),TRUE,M21)} -> 00 | Q21: {=_xlfn.SWITCH(TRUE,OR(L21=TEXT($B$1,"00"),L21=TEXT($D$1,"00")),"00",AND(N21="00",K21<>"TERMINAL"),TEXT($F$2,"00"),TRUE,N21)} -> 00 | R21: =IF(OR(L21="25",L21="26"),TEXT(MAX(VALUE(R20),VALUE(Y20)),"00"),L21) -> 08 | S21: {=_xlfn.SWITCH(TRUE,F21="T",TEXT($F$1,"00"),AND(F21="",K21<>"TERMINAL"),"00",TRUE,TEXT(HOUR(F21),"00"))} -> 08 | T21: {=TEXT(_xlfn.SWITCH(TRUE,F21="T","00",AND(F21="",K21<>"TERMINAL"),"00",TRUE,MINUTE(F21)),"00")} -> 52 | U21: {=TEXT(_xlfn.SWITCH(TRUE,F21="T","00",AND(F21="",K21<>"TERMINAL"),"00",TRUE,SECOND(F21)),"00")} -> 45 | V21: =IF(AND(S21="00",F20<>"t",V20<>"00"),"24",S21) -> 08 | W21: {=_xlfn.SWITCH(TRUE,OR(S21=TEXT($B$1,"00"),S21=TEXT($D$1,"00")),"00",AND(T21="00",K21<>"TERMINAL"),TEXT($D$2,"00"),TRUE,T21)} -> 52 | X21: {=_xlfn.SWITCH(TRUE,OR(S21=TEXT($B$1,"00"),S21=TEXT($D$1,"00")),"00",AND(U21="00",K21<>"TERMINAL"),TEXT($F$2,"00"),TRUE,U21)} -> 45 | Y21: =IF(OR(S21="27"),S20,S21) -> 08 | Z21: =IF(OR(Y21>R21,R21>Y20),"TRUE","FALSE") -> FALSE | AA21: =IF(Z21="TRUE",O21&P21&Q21,IF(OR(L21="25",L21="26"),O21&P21&Q21,"00"&P21&Q21)) -> 250000 | AB21: =IF(Z21="TRUE",V21&W21&X21,IF(S21="27",V21&W21&X21,"00"&W21&X21)) -> 005245 | AC21: {=TEXT($D21,"000")&TEXT(IFERROR(INDEX($D$5:$D$103,_xlfn.AGGREGATE(15,6,ROW($E$5:$E$103)/(($E$5:$E$103<>"p")*($E$5:$E$103<>"t")*(ROW($E$5:$E$103)>ROW($E21))),1)-ROW($E$5)+1),$D21),"000")} -> 080082 | AD21: {=TEXT(_xlfn.XLOOKUP(TRUE, AA22:AA$103<>"250000", AA22:AA$103, "未找到"),"000000")} -> 096015 | AE21: {=_xlfn.SWITCH(TRUE,J21<>"",TEXT(J21,"MMSS"),TRUE,IFERROR(TEXT(E22-F21,"MMSS"),"0000"))} -> 0215
A22: 19 | B22: 間 々 田 | C22: 73595 | D22: 81 | E22: p | F22: 0.37152778 | K22: =IF(E21="着(hh:mm:ss)","start",IF(E22="p","pass",IF(OR(F22="t",K21="terminal"),"terminal","stop"))) -> pass | L22: {=TEXT(_xlfn.SWITCH(TRUE,E22="P",$B$1,AND(E22="",K22<>"TERMINAL"),$D$1,TRUE,HOUR(E22)),"00")} -> 25 | M22: {=TEXT(_xlfn.SWITCH(TRUE,E22="P","00",AND(E22="",K22<>"TERMINAL"),"00",TRUE,MINUTE(E22)),"00")} -> 00 | N22: {=TEXT(_xlfn.SWITCH(TRUE,E22="P","00",AND(E22="",K22<>"TERMINAL"),"00",TRUE,SECOND(E22)),"00")} -> 00 | O22: {=_xlfn.SWITCH(TRUE,AND(L22="00",K22<>"TERMINAL"),TEXT($B$2,"00"),L22=TEXT($B$1,"00"),TEXT($B$1,"00"),L22=TEXT($D$1,"00"),TEXT($D$1,"00"),TRUE,+L22)} -> 25 | P22: {=_xlfn.SWITCH(TRUE,OR(L22=TEXT($B$1,"00"),L22=TEXT($D$1,"00")),"00",AND(M22="00",K22<>"TERMINAL"),TEXT($D$2,"00"),TRUE,M22)} -> 00 | Q22: {=_xlfn.SWITCH(TRUE,OR(L22=TEXT($B$1,"00"),L22=TEXT($D$1,"00")),"00",AND(N22="00",K22<>"TERMINAL"),TEXT($F$2,"00"),TRUE,N22)} -> 00 | R22: =IF(OR(L22="25",L22="26"),TEXT(MAX(VALUE(R21),VALUE(Y21)),"00"),L22) -> 08 | S22: {=_xlfn.SWITCH(TRUE,F22="T",TEXT($F$1,"00"),AND(F22="",K22<>"TERMINAL"),"00",TRUE,TEXT(HOUR(F22),"00"))} -> 08 | T22: {=TEXT(_xlfn.SWITCH(TRUE,F22="T","00",AND(F22="",K22<>"TERMINAL"),"00",TRUE,MINUTE(F22)),"00")} -> 55 | U22: {=TEXT(_xlfn.SWITCH(TRUE,F22="T","00",AND(F22="",K22<>"TERMINAL"),"00",TRUE,SECOND(F22)),"00")} -> 00 | V22: =IF(AND(S22="00",F21<>"t",V21<>"00"),"24",S22) -> 08 | W22: {=_xlfn.SWITCH(TRUE,OR(S22=TEXT($B$1,"00"),S22=TEXT($D$1,"00")),"00",AND(T22="00",K22<>"TERMINAL"),TEXT($D$2,"00"),TRUE,T22)} -> 55 | X22: {=_xlfn.SWITCH(TRUE,OR(S22=TEXT($B$1,"00"),S22=TEXT($D$1,"00")),"00",AND(U22="00",K22<>"TERMINAL"),TEXT($F$2,"00"),TRUE,U22)} -> 60 | Y22: =IF(OR(S22="27"),S21,S22) -> 08 | Z22: =IF(OR(Y22>R22,R22>Y21),"TRUE","FALSE") -> FALSE | AA22: =IF(Z22="TRUE",O22&P22&Q22,IF(OR(L22="25",L22="26"),O22&P22&Q22,"00"&P22&Q22)) -> 250000 | AB22: =IF(Z22="TRUE",V22&W22&X22,IF(S22="27",V22&W22&X22,"00"&W22&X22)) -> 005560 | AC22: {=TEXT($D22,"000")&TEXT(IFERROR(INDEX($D$5:$D$103,_xlfn.AGGREGATE(15,6,ROW($E$5:$E$103)/(($E$5:$E$103<>"p")*($E$5:$E$103<>"t")*(ROW($E$5:$E$103)>ROW($E22))),1)-ROW($E$5)+1),$D22),"000")} -> 081082 | AD22: {=TEXT(_xlfn.XLOOKUP(TRUE, AA23:AA$103<>"250000", AA23:AA$103, "未找到"),"000000")} -> 096015 | AE22: {=_xlfn.SWITCH(TRUE,J22<>"",TEXT(J22,"MMSS"),TRUE,IFERROR(TEXT(E23-F22,"MMSS"),"0000"))} -> 0515
A23: 20 | B23: 小 山 | C23: 80960 | D23: 82 | E23: 0.37517361 | F23: 0.37552083 | J23: =F24-F23 -> 0.0043402778 | K23: =IF(E22="着(hh:mm:ss)","start",IF(E23="p","pass",IF(OR(F23="t",K22="terminal"),"terminal","stop"))) -> stop | L23: {=TEXT(_xlfn.SWITCH(TRUE,E23="P",$B$1,AND(E23="",K23<>"TERMINAL"),$D$1,TRUE,HOUR(E23)),"00")} -> 09 | M23: {=TEXT(_xlfn.SWITCH(TRUE,E23="P","00",AND(E23="",K23<>"TERMINAL"),"00",TRUE,MINUTE(E23)),"00")} -> 00 | N23: {=TEXT(_xlfn.SWITCH(TRUE,E23="P","00",AND(E23="",K23<>"TERMINAL"),"00",TRUE,SECOND(E23)),"00")} -> 15 | O23: {=_xlfn.SWITCH(TRUE,AND(L23="00",K23<>"TERMINAL"),TEXT($B$2,"00"),L23=TEXT($B$1,"00"),TEXT($B$1,"00"),L23=TEXT($D$1,"00"),TEXT($D$1,"00"),TRUE,+L23)} -> 09 | P23: {=_xlfn.SWITCH(TRUE,OR(L23=TEXT($B$1,"00"),L23=TEXT($D$1,"00")),"00",AND(M23="00",K23<>"TERMINAL"),TEXT($D$2,"00"),TRUE,M23)} -> 60 | Q23: {=_xlfn.SWITCH(TRUE,OR(L23=TEXT($B$1,"00"),L23=TEXT($D$1,"00")),"00",AND(N23="00",K23<>"TERMINAL"),TEXT($F$2,"00"),TRUE,N23)} -> 15 | R23: =IF(OR(L23="25",L23="26"),TEXT(MAX(VALUE(R22),VALUE(Y22)),"00"),L23) -> 09 | S23: {=_xlfn.SWITCH(TRUE,F23="T",TEXT($F$1,"00"),AND(F23="",K23<>"TERMINAL"),"00",TRUE,TEXT(HOUR(F23),"00"))} -> 09 | T23: {=TEXT(_xlfn.SWITCH(TRUE,F23="T","00",AND(F23="",K23<>"TERMINAL"),"00",TRUE,MINUTE(F23)),"00")} -> 00 | U23: {=TEXT(_xlfn.SWITCH(TRUE,F23="T","00",AND(F23="",K23<>"TERMINAL"),"00",TRUE,SECOND(F23)),"00")} -> 45 | V23: =IF(AND(S23="00",F22<>"t",V22<>"00"),"24",S23) -> 09 | W23: {=_xlfn.SWITCH(TRUE,OR(S23=TEXT($B$1,"00"),S23=TEXT($D$1,"00")),"00",AND(T23="00",K23<>"TERMINAL"),TEXT($D$2,"00"),TRUE,T23)} -> 60 | X23: {=_xlfn.SWITCH(TRUE,OR(S23=TEXT($B$1,"00"),S23=TEXT($D$1,"00")),"00",AND(U23="00",K23<>"TERMINAL"),TEXT($F$2,"00"),TRUE,U23)} -> 45 | Y23: =IF(OR(S23="27"),S22,S23) -> 09 | Z23: =IF(OR(Y23>R23,R23>Y22),"TRUE","FALSE") -> TRUE | AA23: =IF(Z23="TRUE",O23&P23&Q23,IF(OR(L23="25",L23="26"),O23&P23&Q23,"00"&P23&Q23)) -> 096015 | AB23: =IF(Z23="TRUE",V23&W23&X23,IF(S23="27",V23&W23&X23,"00"&W23&X23)) -> 096045 | AC23: {=TEXT($D23,"000")&TEXT(IFERROR(INDEX($D$5:$D$103,_xlfn.AGGREGATE(15,6,ROW($E$5:$E$103)/(($E$5:$E$103<>"p")*($E$5:$E$103<>"t")*(ROW($E$5:$E$103)>ROW($E23))),1)-ROW($E$5)+1),$D23),"000")} -> 082083 | AD23: {=TEXT(_xlfn.XLOOKUP(TRUE, AA24:AA$103<>"250000", AA24:AA$103, "未找到"),"000000")} -> 000630 | AE23: {=_xlfn.SWITCH(TRUE,J23<>"",TEXT(J23,"MMSS"),TRUE,IFERROR(TEXT(E24-F23,"MMSS"),"0000"))} -> 0615
A24: 21 | B24: 小 金 井 | C24: 88412 | D24: 83 | E24: 0.37951389 | F24: 0.37986111 | J24: =F25-F24 -> 0.0019097222 | K24: =IF(E23="着(hh:mm:ss)","start",IF(E24="p","pass",IF(OR(F24="t",K23="terminal"),"terminal","stop"))) -> stop | L24: {=TEXT(_xlfn.SWITCH(TRUE,E24="P",$B$1,AND(E24="",K24<>"TERMINAL"),$D$1,TRUE,HOUR(E24)),"00")} -> 09 | M24: {=TEXT(_xlfn.SWITCH(TRUE,E24="P","00",AND(E24="",K24<>"TERMINAL"),"00",TRUE,MINUTE(E24)),"00")} -> 06 | N24: {=TEXT(_xlfn.SWITCH(TRUE,E24="P","00",AND(E24="",K24<>"TERMINAL"),"00",TRUE,SECOND(E24)),"00")} -> 30 | O24: {=_xlfn.SWITCH(TRUE,AND(L24="00",K24<>"TERMINAL"),TEXT($B$2,"00"),L24=TEXT($B$1,"00"),TEXT($B$1,"00"),L24=TEXT($D$1,"00"),TEXT($D$1,"00"),TRUE,+L24)} -> 09 | P24: {=_xlfn.SWITCH(TRUE,OR(L24=TEXT($B$1,"00"),L24=TEXT($D$1,"00")),"00",AND(M24="00",K24<>"TERMINAL"),TEXT($D$2,"00"),TRUE,M24)} -> 06 | Q24: {=_xlfn.SWITCH(TRUE,OR(L24=TEXT($B$1,"00"),L24=TEXT($D$1,"00")),"00",AND(N24="00",K24<>"TERMINAL"),TEXT($F$2,"00"),TRUE,N24)} -> 30 | R24: =IF(OR(L24="25",L24="26"),TEXT(MAX(VALUE(R23),VALUE(Y23)),"00"),L24) -> 09 | S24: {=_xlfn.SWITCH(TRUE,F24="T",TEXT($F$1,"00"),AND(F24="",K24<>"TERMINAL"),"00",TRUE,TEXT(HOUR(F24),"00"))} -> 09 | T24: {=TEXT(_xlfn.SWITCH(TRUE,F24="T","00",AND(F24="",K24<>"TERMINAL"),"00",TRUE,MINUTE(F24)),"00")} -> 07 | U24: {=TEXT(_xlfn.SWITCH(TRUE,F24="T","00",AND(F24="",K24<>"TERMINAL"),"00",TRUE,SECOND(F24)),"00")} -> 00 | V24: =IF(AND(S24="00",F23<>"t",V23<>"00"),"24",S24) -> 09 | W24: {=_xlfn.SWITCH(TRUE,OR(S24=TEXT($B$1,"00"),S24=TEXT($D$1,"00")),"00",AND(T24="00",K24<>"TERMINAL"),TEXT($D$2,"00"),TRUE,T24)} -> 07 | X24: {=_xlfn.SWITCH(TRUE,OR(S24=TEXT($B$1,"00"),S24=TEXT($D$1,"00")),"00",AND(U24="00",K24<>"TERMINAL"),TEXT($F$2,"00"),TRUE,U24)} -> 60 | Y24: =IF(OR(S24="27"),S23,S24) -> 09 | Z24: =IF(OR(Y24>R24,R24>Y23),"TRUE","FALSE") -> FALSE | AA24: =IF(Z24="TRUE",O24&P24&Q24,IF(OR(L24="25",L24="26"),O24&P24&Q24,"00"&P24&Q24)) -> 000630 | AB24: =IF(Z24="TRUE",V24&W24&X24,IF(S24="27",V24&W24&X24,"00"&W24&X24)) -> 000760 | AC24: {=TEXT($D24,"000")&TEXT(IFERROR(INDEX($D$5:$D$103,_xlfn.AGGREGATE(15,6,ROW($E$5:$E$103)/(($E$5:$E$103<>"p")*($E$5:$E$103<>"t")*(ROW($E$5:$E$103)>ROW($E24))),1)-ROW($E$5)+1),$D24),"000")} -> 083084 | AD24: {=TEXT(_xlfn.XLOOKUP(TRUE, AA25:AA$103<>"250000", AA25:AA$103, "未找到"),"000000")} -> 000915 | AE24: {=_xlfn.SWITCH(TRUE,J24<>"",TEXT(J24,"MMSS"),TRUE,IFERROR(TEXT(E25-F24,"MMSS"),"0000"))} -> 0245
A25: 22 | B25: 自治医大 | C25: 91012 | D25: 84 | E25: 0.38142361 | F25: 0.38177083 | J25: =F26-F25 -> 0.0036458333 | K25: =IF(E24="着(hh:mm:ss)","start",IF(E25="p","pass",IF(OR(F25="t",K24="terminal"),"terminal","stop"))) -> stop | L25: {=TEXT(_xlfn.SWITCH(TRUE,E25="P",$B$1,AND(E25="",K25<>"TERMINAL"),$D$1,TRUE,HOUR(E25)),"00")} -> 09 | M25: {=TEXT(_xlfn.SWITCH(TRUE,E25="P","00",AND(E25="",K25<>"TERMINAL"),"00",TRUE,MINUTE(E25)),"00")} -> 09 | N25: {=TEXT(_xlfn.SWITCH(TRUE,E25="P","00",AND(E25="",K25<>"TERMINAL"),"00",TRUE,SECOND(E25)),"00")} -> 15 | O25: {=_xlfn.SWITCH(TRUE,AND(L25="00",K25<>"TERMINAL"),TEXT($B$2,"00"),L25=TEXT($B$1,"00"),TEXT($B$1,"00"),L25=TEXT($D$1,"00"),TEXT($D$1,"00"),TRUE,+L25)} -> 09 | P25: {=_xlfn.SWITCH(TRUE,OR(L25=TEXT($B$1,"00"),L25=TEXT($D$1,"00")),"00",AND(M25="00",K25<>"TERMINAL"),TEXT($D$2,"00"),TRUE,M25)} -> 09 | Q25: {=_xlfn.SWITCH(TRUE,OR(L25=TEXT($B$1,"00"),L25=TEXT($D$1,"00")),"00",AND(N25="00",K25<>"TERMINAL"),TEXT($F$2,"00"),TRUE,N25)} -> 15 | R25: =IF(OR(L25="25",L25="26"),TEXT(MAX(VALUE(R24),VALUE(Y24)),"00"),L25) -> 09 | S25: {=_xlfn.SWITCH(TRUE,F25="T",TEXT($F$1,"00"),AND(F25="",K25<>"TERMINAL"),"00",TRUE,TEXT(HOUR(F25),"00"))} -> 09 | T25: {=TEXT(_xlfn.SWITCH(TRUE,F25="T","00",AND(F25="",K25<>"TERMINAL"),"00",TRUE,MINUTE(F25)),"00")} -> 09 | U25: {=TEXT(_xlfn.SWITCH(TRUE,F25="T","00",AND(F25="",K25<>"TERMINAL"),"00",TRUE,SECOND(F25)),"00")} -> 45 | V25: =IF(AND(S25="00",F24<>"t",V24<>"00"),"24",S25) -> 09 | W25: {=_xlfn.SWITCH(TRUE,OR(S25=TEXT($B$1,"00"),S25=TEXT($D$1,"00")),"00",AND(T25="00",K25<>"TERMINAL"),TEXT($D$2,"00"),TRUE,T25)} -> 09 | X25: {=_xlfn.SWITCH(TRUE,OR(S25=TEXT($B$1,"00"),S25=TEXT($D$1,"00")),"00",AND(U25="00",K25<>"TERMINAL"),TEXT($F$2,"00"),TRUE,U25)} -> 45 | Y25: =IF(OR(S25="27"),S24,S25) -> 09 | Z25: =IF(OR(Y25>R25,R25>Y24),"TRUE","FALSE") -> FALSE | AA25: =IF(Z25="TRUE",O25&P25&Q25,IF(OR(L25="25",L25="26"),O25&P25&Q25,"00"&P25&Q25)) -> 000915 | AB25: =IF(Z25="TRUE",V25&W25&X25,IF(S25="27",V25&W25&X25,"00"&W25&X25)) -> 000945 | AC25: {=TEXT($D25,"000")&TEXT(IFERROR(INDEX($D$5:$D$103,_xlfn.AGGREGATE(15,6,ROW($E$5:$E$103)/(($E$5:$E$103<>"p")*($E$5:$E$103<>"t")*(ROW($E$5:$E$103)>ROW($E25))),1)-ROW($E$5)+1),$D25),"000")} -> 084085 | AD25: {=TEXT(_xlfn.XLOOKUP(TRUE, AA26:AA$103<>"250000", AA26:AA$103, "未找到"),"000000")} -> 001430 | AE25: {=_xlfn.SWITCH(TRUE,J25<>"",TEXT(J25,"MMSS"),TRUE,IFERROR(TEXT(E26-F25,"MMSS"),"0000"))} -> 0515
A26: 23 | B26: 石 橋 | C26: 95735 | D26: 85 | E26: 0.38506944 | F26: 0.38541667 | J26: =F27-F26 -> 0.0019097222 | K26: =IF(E25="着(hh:mm:ss)","start",IF(E26="p","pass",IF(OR(F26="t",K25="terminal"),"terminal","stop"))) -> stop | L26: {=TEXT(_xlfn.SWITCH(TRUE,E26="P",$B$1,AND(E26="",K26<>"TERMINAL"),$D$1,TRUE,HOUR(E26)),"00")} -> 09 | M26: {=TEXT(_xlfn.SWITCH(TRUE,E26="P","00",AND(E26="",K26<>"TERMINAL"),"00",TRUE,MINUTE(E26)),"00")} -> 14 | N26: {=TEXT(_xlfn.SWITCH(TRUE,E26="P","00",AND(E26="",K26<>"TERMINAL"),"00",TRUE,SECOND(E26)),"00")} -> 30 | O26: {=_xlfn.SWITCH(TRUE,AND(L26="00",K26<>"TERMINAL"),TEXT($B$2,"00"),L26=TEXT($B$1,"00"),TEXT($B$1,"00"),L26=TEXT($D$1,"00"),TEXT($D$1,"00"),TRUE,+L26)} -> 09 | P26: {=_xlfn.SWITCH(TRUE,OR(L26=TEXT($B$1,"00"),L26=TEXT($D$1,"00")),"00",AND(M26="00",K26<>"TERMINAL"),TEXT($D$2,"00"),TRUE,M26)} -> 14 | Q26: {=_xlfn.SWITCH(TRUE,OR(L26=TEXT($B$1,"00"),L26=TEXT($D$1,"00")),"00",AND(N26="00",K26<>"TERMINAL"),TEXT($F$2,"00"),TRUE,N26)} -> 30 | R26: =IF(OR(L26="25",L26="26"),TEXT(MAX(VALUE(R25),VALUE(Y25)),"00"),L26) -> 09 | S26: {=_xlfn.SWITCH(TRUE,F26="T",TEXT($F$1,"00"),AND(F26="",K26<>"TERMINAL"),"00",TRUE,TEXT(HOUR(F26),"00"))} -> 09 | T26: {=TEXT(_xlfn.SWITCH(TRUE,F26="T","00",AND(F26="",K26<>"TERMINAL"),"00",TRUE,MINUTE(F26)),"00")} -> 15 | U26: {=TEXT(_xlfn.SWITCH(TRUE,F26="T","00",AND(F26="",K26<>"TERMINAL"),"00",TRUE,SECOND(F26)),"00")} -> 00 | V26: =IF(AND(S26="00",F25<>"t",V25<>"00"),"24",S26) -> 09 | W26: {=_xlfn.SWITCH(TRUE,OR(S26=TEXT($B$1,"00"),S26=TEXT($D$1,"00")),"00",AND(T26="00",K26<>"TERMINAL"),TEXT($D$2,"00"),TRUE,T26)} -> 15 | X26: {=_xlfn.SWITCH(TRUE,OR(S26=TEXT($B$1,"00"),S26=TEXT($D$1,"00")),"00",AND(U26="00",K26<>"TERMINAL"),TEXT($F$2,"00"),TRUE,U26)} -> 60 | Y26: =IF(OR(S26="27"),S25,S26) -> 09 | Z26: =IF(OR(Y26>R26,R26>Y25),"TRUE","FALSE") -> FALSE | AA26: =IF(Z26="TRUE",O26&P26&Q26,IF(OR(L26="25",L26="26"),O26&P26&Q26,"00"&P26&Q26)) -> 001430 | AB26: =IF(Z26="TRUE",V26&W26&X26,IF(S26="27",V26&W26&X26,"00"&W26&X26)) -> 001560 | AC26: {=TEXT($D26,"000")&TEXT(IFERROR(INDEX($D$5:$D$103,_xlfn.AGGREGATE(15,6,ROW($E$5:$E$103)/(($E$5:$E$103<>"p")*($E$5:$E$103<>"t")*(ROW($E$5:$E$103)>ROW($E26))),1)-ROW($E$5)+1),$D26),"000")} -> 085087 | AD26: {=TEXT(_xlfn.XLOOKUP(TRUE, AA27:AA$103<>"250000", AA27:AA$103, "未找到"),"000000")} -> 002060 | AE26: {=_xlfn.SWITCH(TRUE,J26<>"",TEXT(J26,"MMSS"),TRUE,IFERROR(TEXT(E27-F26,"MMSS"),"0000"))} -> 0245
A27: 24 | B27: 宇都宮タ | C27: 98975 | D27: 86 | E27: p | F27: 0.38732639 | K27: =IF(E26="着(hh:mm:ss)","start",IF(E27="p","pass",IF(OR(F27="t",K26="terminal"),"terminal","stop"))) -> pass | L27: {=TEXT(_xlfn.SWITCH(TRUE,E27="P",$B$1,AND(E27="",K27<>"TERMINAL"),$D$1,TRUE,HOUR(E27)),"00")} -> 25 | M27: {=TEXT(_xlfn.SWITCH(TRUE,E27="P","00",AND(E27="",K27<>"TERMINAL"),"00",TRUE,MINUTE(E27)),"00")} -> 00 | N27: {=TEXT(_xlfn.SWITCH(TRUE,E27="P","00",AND(E27="",K27<>"TERMINAL"),"00",TRUE,SECOND(E27)),"00")} -> 00 | O27: {=_xlfn.SWITCH(TRUE,AND(L27="00",K27<>"TERMINAL"),TEXT($B$2,"00"),L27=TEXT($B$1,"00"),TEXT($B$1,"00"),L27=TEXT($D$1,"00"),TEXT($D$1,"00"),TRUE,+L27)} -> 25 | P27: {=_xlfn.SWITCH(TRUE,OR(L27=TEXT($B$1,"00"),L27=TEXT($D$1,"00")),"00",AND(M27="00",K27<>"TERMINAL"),TEXT($D$2,"00"),TRUE,M27)} -> 00 | Q27: {=_xlfn.SWITCH(TRUE,OR(L27=TEXT($B$1,"00"),L27=TEXT($D$1,"00")),"00",AND(N27="00",K27<>"TERMINAL"),TEXT($F$2,"00"),TRUE,N27)} -> 00 | R27: =IF(OR(L27="25",L27="26"),TEXT(MAX(VALUE(R26),VALUE(Y26)),"00"),L27) -> 09 | S27: {=_xlfn.SWITCH(TRUE,F27="T",TEXT($F$1,"00"),AND(F27="",K27<>"TERMINAL"),"00",TRUE,TEXT(HOUR(F27),"00"))} -> 09 | T27: {=TEXT(_xlfn.SWITCH(TRUE,F27="T","00",AND(F27="",K27<>"TERMINAL"),"00",TRUE,MINUTE(F27)),"00")} -> 17 | U27: {=TEXT(_xlfn.SWITCH(TRUE,F27="T","00",AND(F27="",K27<>"TERMINAL"),"00",TRUE,SECOND(F27)),"00")} -> 45 | V27: =IF(AND(S27="00",F26<>"t",V26<>"00"),"24",S27) -> 09 | W27: {=_xlfn.SWITCH(TRUE,OR(S27=TEXT($B$1,"00"),S27=TEXT($D$1,"00")),"00",AND(T27="00",K27<>"TERMINAL"),TEXT($D$2,"00"),TRUE,T27)} -> 17 | X27: {=_xlfn.SWITCH(TRUE,OR(S27=TEXT($B$1,"00"),S27=TEXT($D$1,"00")),"00",AND(U27="00",K27<>"TERMINAL"),TEXT($F$2,"00"),TRUE,U27)} -> 45 | Y27: =IF(OR(S27="27"),S26,S27) -> 09 | Z27: =IF(OR(Y27>R27,R27>Y26),"TRUE","FALSE") -> FALSE | AA27: =IF(Z27="TRUE",O27&P27&Q27,IF(OR(L27="25",L27="26"),O27&P27&Q27,"00"&P27&Q27)) -> 250000 | AB27: =IF(Z27="TRUE",V27&W27&X27,IF(S27="27",V27&W27&X27,"00"&W27&X27)) -> 001745 | AC27: {=TEXT($D27,"000")&TEXT(IFERROR(INDEX($D$5:$D$103,_xlfn.AGGREGATE(15,6,ROW($E$5:$E$103)/(($E$5:$E$103<>"p")*($E$5:$E$103<>"t")*(ROW($E$5:$E$103)>ROW($E27))),1)-ROW($E$5)+1),$D27),"000")} -> 086087 | AD27: {=TEXT(_xlfn.XLOOKUP(TRUE, AA28:AA$103<>"250000", AA28:AA$103, "未找到"),"000000")} -> 002060 | AE27: {=_xlfn.SWITCH(TRUE,J27<>"",TEXT(J27,"MMSS"),TRUE,IFERROR(TEXT(E28-F27,"MMSS"),"0000"))} -> 0215
